2014-10-14 10:45:14,647 INFO: ERROR:404: IP:113.57.245.36 REQUEST URL:http://news.future.org.cn/article/ [in /home/future/wwwroot/news/news/controller/errorHandler.py:19]
2014-10-14 10:45:14,648 INFO: Header:Content-Length: 
Accept-Charset: utf-8, iso-8859-1, utf-16, *;q=0.7
User-Agent: Mozilla/5.0 (Linux; U; Android 4.1.2; zh-cn; LT26i Build/6.2.B.1.96) AppleWebKit/533.1 (KHTML, like Gecko)Version/4.0 MQQBrowser/5.4 Mobile Safari/533.1 V1_AND_SQ_5.1.1_158_YYB_D QQ/5.1.1.2245
Connection: keep-alive
Host: news.future.org.cn
Accept: application/vnd.wap.xhtml+xml, text/vnd.wap.wml, application/xhtml+xml, text/html, image/png, image/jpeg, image/gif, */*;q=0.1
Accept-Language: zh-CN
Content-Type: 
Accept-Encoding: gzip

 [in /home/future/wwwroot/news/news/controller/errorHandler.py:20]
2014-10-14 16:00:29,941 INFO: ERROR:404: IP:210.41.201.8 REQUEST URL:http://news.future.org.cn/favicon.ico [in /home/future/wwwroot/news/news/controller/errorHandler.py:19]
2014-10-14 16:00:29,942 INFO: Header:Content-Length: 
User-Agent: Mozilla/5.0 (Windows NT 5.1) AppleWebKit/537.36 (KHTML, like Gecko) Chrome/31.0.1650.63 Safari/537.36 SE 2.X MetaSr 1.0
Connection: Keep-Alive
Host: news.future.org.cn
Content-Type: 
Accept-Encoding: gzip, deflate

 [in /home/future/wwwroot/news/news/controller/errorHandler.py:20]
2014-10-15 09:25:35,377 ERROR: Exception on /article/58246 [GET] [in /usr/lib/python2.7/dist-packages/flask/app.py:1423]
Traceback (most recent call last):
  File "/usr/lib/python2.7/dist-packages/flask/app.py", line 1817, in wsgi_app
    response = self.full_dispatch_request()
  File "/usr/lib/python2.7/dist-packages/flask/app.py", line 1477, in full_dispatch_request
    rv = self.handle_user_exception(e)
  File "/usr/lib/python2.7/dist-packages/flask/app.py", line 1381, in handle_user_exception
    reraise(exc_type, exc_value, tb)
  File "/usr/lib/python2.7/dist-packages/flask/app.py", line 1475, in full_dispatch_request
    rv = self.dispatch_request()
  File "/usr/lib/python2.7/dist-packages/flask/app.py", line 1461, in dispatch_request
    return self.view_functions[rule.endpoint](**req.view_args)
  File "/home/future/wwwroot/news/news/controller/article.py", line 88, in viewfrontArticle
    article=db_article.Article().getArticleByid(id)
  File "/home/future/wwwroot/news/news/model/article.py", line 96, in getArticleByid
    return session.query(Article).filter(Article.id == id).first()
  File "/home/future/wwwroot/news/env/local/lib/python2.7/site-packages/sqlalchemy/orm/query.py", line 2334, in first
    ret = list(self[0:1])
  File "/home/future/wwwroot/news/env/local/lib/python2.7/site-packages/sqlalchemy/orm/query.py", line 2201, in __getitem__
    return list(res)
  File "/home/future/wwwroot/news/env/local/lib/python2.7/site-packages/sqlalchemy/orm/query.py", line 2405, in __iter__
    return self._execute_and_instances(context)
  File "/home/future/wwwroot/news/env/local/lib/python2.7/site-packages/sqlalchemy/orm/query.py", line 2420, in _execute_and_instances
    result = conn.execute(querycontext.statement, self._params)
  File "/home/future/wwwroot/news/env/local/lib/python2.7/site-packages/sqlalchemy/engine/base.py", line 727, in execute
    return meth(self, multiparams, params)
  File "/home/future/wwwroot/news/env/local/lib/python2.7/site-packages/sqlalchemy/sql/elements.py", line 322, in _execute_on_connection
    return connection._execute_clauseelement(self, multiparams, params)
  File "/home/future/wwwroot/news/env/local/lib/python2.7/site-packages/sqlalchemy/engine/base.py", line 824, in _execute_clauseelement
    compiled_sql, distilled_params
  File "/home/future/wwwroot/news/env/local/lib/python2.7/site-packages/sqlalchemy/engine/base.py", line 954, in _execute_context
    context)
  File "/home/future/wwwroot/news/env/local/lib/python2.7/site-packages/sqlalchemy/engine/base.py", line 1116, in _handle_dbapi_exception
    exc_info
  File "/home/future/wwwroot/news/env/local/lib/python2.7/site-packages/sqlalchemy/util/compat.py", line 189, in raise_from_cause
    reraise(type(exception), exception, tb=exc_tb)
  File "/home/future/wwwroot/news/env/local/lib/python2.7/site-packages/sqlalchemy/engine/base.py", line 947, in _execute_context
    context)
  File "/home/future/wwwroot/news/env/local/lib/python2.7/site-packages/sqlalchemy/engine/default.py", line 435, in do_execute
    cursor.execute(statement, parameters)
  File "/usr/local/lib/python2.7/dist-packages/MySQLdb/cursors.py", line 205, in execute
    self.errorhandler(self, exc, value)
  File "/usr/local/lib/python2.7/dist-packages/MySQLdb/connections.py", line 36, in defaulterrorhandler
    raise errorclass, errorvalue
OperationalError: (OperationalError) (2006, 'MySQL server has gone away') 'SELECT news_article.id AS news_article_id, news_article.categoryid AS news_article_categoryid, news_article.title AS news_article_title, news_article.publisher AS news_article_publisher, news_article.author AS news_article_author, news_article.editor AS news_article_editor, news_article.`publishTime` AS `news_article_publishTime`, news_article.`updateTime` AS `news_article_updateTime`, news_article.content AS news_article_content, news_article.views AS news_article_views, news_article.state AS news_article_state, news_article.checker1 AS news_article_checker1, news_article.checker2 AS news_article_checker2 \nFROM news_article \nWHERE news_article.id = %s \n LIMIT %s' (58246, 1)
2014-10-15 09:25:35,611 ERROR: ERROR:500: IP:218.197.159.215 REQUEST URL:http://news.future.org.cn/article/58246 [in /home/future/wwwroot/news/news/controller/errorHandler.py:7]
2014-10-15 09:25:35,808 ERROR: Header:Referer: http://mp.weixin.qq.com/mp/redirect?url=http%3A%2F%2Fnews.future.org.cn%2Farticle%2F58246%23rd
Content-Length: 
User-Agent: Mozilla/5.0 (iPad; CPU OS 8_0_2 like Mac OS X) AppleWebKit/600.1.4 (KHTML, like Gecko) Mobile/12A405 MicroMessenger/6.0 NetType/WIFI
Connection: keep-alive
Cookie: CNZZDATA1000537224=1990527564-1413336037-http%253A%252F%252Fmp.weixin.qq.com%252F%7C1413336037
Host: news.future.org.cn
Accept: text/html,application/xhtml+xml,application/xml;q=0.9,*/*;q=0.8
Accept-Language: zh-cn
Content-Type: 
Accept-Encoding: gzip, deflate

 [in /home/future/wwwroot/news/news/controller/errorHandler.py:8]
2014-10-15 09:49:38,309 INFO: ERROR:404: IP:202.114.99.40 REQUEST URL:http://news.future.org.cn/favicon.ico [in /home/future/wwwroot/news/news/controller/errorHandler.py:19]
2014-10-15 09:49:38,310 INFO: Header:Cookie: session=eyJwYXNzd29yZCI6IjEyMzQ1NiJ9.Bx9kMQ.e6KBB6ibC97USrLvbx5vAJ3gZEw; CNZZDATA1000537224=337043770-1411433109-http%253A%252F%252Fwww.future.org.cn%252F%7C1413337284
Content-Length: 
User-Agent: Mozilla/5.0 (Windows NT 6.1; WOW64) AppleWebKit/537.36 (KHTML, like Gecko) Chrome/37.0.2062.124 Safari/537.36
Connection: Keep-Alive
Via: 1.1 FUTURE40
Host: news.future.org.cn
Accept: */*
Accept-Language: zh-CN,zh;q=0.8
Content-Type: 

 [in /home/future/wwwroot/news/news/controller/errorHandler.py:20]
2014-10-15 10:11:27,775 ERROR: Exception on /article/58267 [GET] [in /usr/lib/python2.7/dist-packages/flask/app.py:1423]
Traceback (most recent call last):
  File "/usr/lib/python2.7/dist-packages/flask/app.py", line 1817, in wsgi_app
    response = self.full_dispatch_request()
  File "/usr/lib/python2.7/dist-packages/flask/app.py", line 1477, in full_dispatch_request
    rv = self.handle_user_exception(e)
  File "/usr/lib/python2.7/dist-packages/flask/app.py", line 1381, in handle_user_exception
    reraise(exc_type, exc_value, tb)
  File "/usr/lib/python2.7/dist-packages/flask/app.py", line 1475, in full_dispatch_request
    rv = self.dispatch_request()
  File "/usr/lib/python2.7/dist-packages/flask/app.py", line 1461, in dispatch_request
    return self.view_functions[rule.endpoint](**req.view_args)
  File "/home/future/wwwroot/news/news/controller/article.py", line 88, in viewfrontArticle
    article=db_article.Article().getArticleByid(id)
  File "/home/future/wwwroot/news/news/model/article.py", line 96, in getArticleByid
    return session.query(Article).filter(Article.id == id).first()
  File "/home/future/wwwroot/news/env/local/lib/python2.7/site-packages/sqlalchemy/orm/query.py", line 2334, in first
    ret = list(self[0:1])
  File "/home/future/wwwroot/news/env/local/lib/python2.7/site-packages/sqlalchemy/orm/query.py", line 2201, in __getitem__
    return list(res)
  File "/home/future/wwwroot/news/env/local/lib/python2.7/site-packages/sqlalchemy/orm/query.py", line 2405, in __iter__
    return self._execute_and_instances(context)
  File "/home/future/wwwroot/news/env/local/lib/python2.7/site-packages/sqlalchemy/orm/query.py", line 2420, in _execute_and_instances
    result = conn.execute(querycontext.statement, self._params)
  File "/home/future/wwwroot/news/env/local/lib/python2.7/site-packages/sqlalchemy/engine/base.py", line 727, in execute
    return meth(self, multiparams, params)
  File "/home/future/wwwroot/news/env/local/lib/python2.7/site-packages/sqlalchemy/sql/elements.py", line 322, in _execute_on_connection
    return connection._execute_clauseelement(self, multiparams, params)
  File "/home/future/wwwroot/news/env/local/lib/python2.7/site-packages/sqlalchemy/engine/base.py", line 824, in _execute_clauseelement
    compiled_sql, distilled_params
  File "/home/future/wwwroot/news/env/local/lib/python2.7/site-packages/sqlalchemy/engine/base.py", line 891, in _execute_context
    None, None)
  File "/home/future/wwwroot/news/env/local/lib/python2.7/site-packages/sqlalchemy/engine/base.py", line 1116, in _handle_dbapi_exception
    exc_info
  File "/home/future/wwwroot/news/env/local/lib/python2.7/site-packages/sqlalchemy/util/compat.py", line 189, in raise_from_cause
    reraise(type(exception), exception, tb=exc_tb)
  File "/home/future/wwwroot/news/env/local/lib/python2.7/site-packages/sqlalchemy/engine/base.py", line 885, in _execute_context
    conn = self._revalidate_connection()
  File "/home/future/wwwroot/news/env/local/lib/python2.7/site-packages/sqlalchemy/engine/base.py", line 241, in _revalidate_connection
    "Can't reconnect until invalid "
StatementError: Can't reconnect until invalid transaction is rolled back (original cause: InvalidRequestError: Can't reconnect until invalid transaction is rolled back) u'SELECT news_article.id AS news_article_id, news_article.categoryid AS news_article_categoryid, news_article.title AS news_article_title, news_article.publisher AS news_article_publisher, news_article.author AS news_article_author, news_article.editor AS news_article_editor, news_article.`publishTime` AS `news_article_publishTime`, news_article.`updateTime` AS `news_article_updateTime`, news_article.content AS news_article_content, news_article.views AS news_article_views, news_article.state AS news_article_state, news_article.checker1 AS news_article_checker1, news_article.checker2 AS news_article_checker2 \nFROM news_article \nWHERE news_article.id = %s \n LIMIT %s' [immutabledict({})]
2014-10-15 10:11:27,987 ERROR: ERROR:500: IP:101.226.66.21 REQUEST URL:http://news.future.org.cn/article/58267 [in /home/future/wwwroot/news/news/controller/errorHandler.py:7]
2014-10-15 10:11:28,181 ERROR: Header:Content-Length: 
Accept-Charset: GB2312,utf-8;q=0.7,*;q=0.7
User-Agent: Mozilla/4.0
Connection: close
Host: news.future.org.cn
Accept: */*
Accept-Language: zh-cn, zh
Content-Type: 

 [in /home/future/wwwroot/news/news/controller/errorHandler.py:8]
2014-10-15 11:16:22,051 ERROR: Exception on /category/13/page/4 [GET] [in /usr/lib/python2.7/dist-packages/flask/app.py:1423]
Traceback (most recent call last):
  File "/usr/lib/python2.7/dist-packages/flask/app.py", line 1817, in wsgi_app
    response = self.full_dispatch_request()
  File "/usr/lib/python2.7/dist-packages/flask/app.py", line 1477, in full_dispatch_request
    rv = self.handle_user_exception(e)
  File "/usr/lib/python2.7/dist-packages/flask/app.py", line 1381, in handle_user_exception
    reraise(exc_type, exc_value, tb)
  File "/usr/lib/python2.7/dist-packages/flask/app.py", line 1475, in full_dispatch_request
    rv = self.dispatch_request()
  File "/usr/lib/python2.7/dist-packages/flask/app.py", line 1461, in dispatch_request
    return self.view_functions[rule.endpoint](**req.view_args)
  File "/home/future/wwwroot/news/news/controller/category.py", line 15, in viewCategory
    category=db_category.Category().getCategortByid(id)
  File "/home/future/wwwroot/news/news/model/category.py", line 61, in getCategortByid
    return session.query(Category).filter(Category.id == id).first()
  File "/home/future/wwwroot/news/env/local/lib/python2.7/site-packages/sqlalchemy/orm/query.py", line 2334, in first
    ret = list(self[0:1])
  File "/home/future/wwwroot/news/env/local/lib/python2.7/site-packages/sqlalchemy/orm/query.py", line 2201, in __getitem__
    return list(res)
  File "/home/future/wwwroot/news/env/local/lib/python2.7/site-packages/sqlalchemy/orm/query.py", line 2405, in __iter__
    return self._execute_and_instances(context)
  File "/home/future/wwwroot/news/env/local/lib/python2.7/site-packages/sqlalchemy/orm/query.py", line 2420, in _execute_and_instances
    result = conn.execute(querycontext.statement, self._params)
  File "/home/future/wwwroot/news/env/local/lib/python2.7/site-packages/sqlalchemy/engine/base.py", line 727, in execute
    return meth(self, multiparams, params)
  File "/home/future/wwwroot/news/env/local/lib/python2.7/site-packages/sqlalchemy/sql/elements.py", line 322, in _execute_on_connection
    return connection._execute_clauseelement(self, multiparams, params)
  File "/home/future/wwwroot/news/env/local/lib/python2.7/site-packages/sqlalchemy/engine/base.py", line 824, in _execute_clauseelement
    compiled_sql, distilled_params
  File "/home/future/wwwroot/news/env/local/lib/python2.7/site-packages/sqlalchemy/engine/base.py", line 891, in _execute_context
    None, None)
  File "/home/future/wwwroot/news/env/local/lib/python2.7/site-packages/sqlalchemy/engine/base.py", line 1116, in _handle_dbapi_exception
    exc_info
  File "/home/future/wwwroot/news/env/local/lib/python2.7/site-packages/sqlalchemy/util/compat.py", line 189, in raise_from_cause
    reraise(type(exception), exception, tb=exc_tb)
  File "/home/future/wwwroot/news/env/local/lib/python2.7/site-packages/sqlalchemy/engine/base.py", line 885, in _execute_context
    conn = self._revalidate_connection()
  File "/home/future/wwwroot/news/env/local/lib/python2.7/site-packages/sqlalchemy/engine/base.py", line 241, in _revalidate_connection
    "Can't reconnect until invalid "
StatementError: Can't reconnect until invalid transaction is rolled back (original cause: InvalidRequestError: Can't reconnect until invalid transaction is rolled back) u'SELECT news_category.id AS news_category_id, news_category.parentid AS news_category_parentid, news_category.categoryname AS news_category_categoryname \nFROM news_category \nWHERE news_category.id = %s \n LIMIT %s' [immutabledict({})]
2014-10-15 11:16:22,254 ERROR: ERROR:500: IP:182.118.25.223 REQUEST URL:http://news.future.org.cn/category/13/page/4 [in /home/future/wwwroot/news/news/controller/errorHandler.py:7]
2014-10-15 11:16:22,451 ERROR: Header:Referer: http://news.future.org.cn/category/13/page/4
Content-Length: 
User-Agent: Mozilla/5.0 (compatible; MSIE 9.0; Windows NT 6.1; Trident/5.0); 360Spider
Connection: Keep-Alive
Host: news.future.org.cn
Accept: */*
Accept-Language: zh-CN
Content-Type: 
Accept-Encoding: deflate, gzip

 [in /home/future/wwwroot/news/news/controller/errorHandler.py:8]
2014-10-15 12:37:22,214 INFO: ERROR:404: IP:42.156.136.108 REQUEST URL:http://news.future.org.cn/articles/73062.html [in /home/future/wwwroot/news/news/controller/errorHandler.py:19]
2014-10-15 12:37:22,215 INFO: Header:Content-Length: 
User-Agent: YisouSpider
Connection: Keep-Alive
Host: news.future.org.cn
Accept: */*
Accept-Language: zh-cn,en-us,zh-tw,en-gb,en;
Content-Type: 
Accept-Encoding: gzip

 [in /home/future/wwwroot/news/news/controller/errorHandler.py:20]
2014-10-15 13:00:34,847 ERROR: Exception on /article/22946 [GET] [in /usr/lib/python2.7/dist-packages/flask/app.py:1423]
Traceback (most recent call last):
  File "/usr/lib/python2.7/dist-packages/flask/app.py", line 1817, in wsgi_app
    response = self.full_dispatch_request()
  File "/usr/lib/python2.7/dist-packages/flask/app.py", line 1477, in full_dispatch_request
    rv = self.handle_user_exception(e)
  File "/usr/lib/python2.7/dist-packages/flask/app.py", line 1381, in handle_user_exception
    reraise(exc_type, exc_value, tb)
  File "/usr/lib/python2.7/dist-packages/flask/app.py", line 1475, in full_dispatch_request
    rv = self.dispatch_request()
  File "/usr/lib/python2.7/dist-packages/flask/app.py", line 1461, in dispatch_request
    return self.view_functions[rule.endpoint](**req.view_args)
  File "/home/future/wwwroot/news/news/controller/article.py", line 88, in viewfrontArticle
    article=db_article.Article().getArticleByid(id)
  File "/home/future/wwwroot/news/news/model/article.py", line 96, in getArticleByid
    return session.query(Article).filter(Article.id == id).first()
  File "/home/future/wwwroot/news/env/local/lib/python2.7/site-packages/sqlalchemy/orm/query.py", line 2334, in first
    ret = list(self[0:1])
  File "/home/future/wwwroot/news/env/local/lib/python2.7/site-packages/sqlalchemy/orm/query.py", line 2201, in __getitem__
    return list(res)
  File "/home/future/wwwroot/news/env/local/lib/python2.7/site-packages/sqlalchemy/orm/query.py", line 2405, in __iter__
    return self._execute_and_instances(context)
  File "/home/future/wwwroot/news/env/local/lib/python2.7/site-packages/sqlalchemy/orm/query.py", line 2420, in _execute_and_instances
    result = conn.execute(querycontext.statement, self._params)
  File "/home/future/wwwroot/news/env/local/lib/python2.7/site-packages/sqlalchemy/engine/base.py", line 727, in execute
    return meth(self, multiparams, params)
  File "/home/future/wwwroot/news/env/local/lib/python2.7/site-packages/sqlalchemy/sql/elements.py", line 322, in _execute_on_connection
    return connection._execute_clauseelement(self, multiparams, params)
  File "/home/future/wwwroot/news/env/local/lib/python2.7/site-packages/sqlalchemy/engine/base.py", line 824, in _execute_clauseelement
    compiled_sql, distilled_params
  File "/home/future/wwwroot/news/env/local/lib/python2.7/site-packages/sqlalchemy/engine/base.py", line 891, in _execute_context
    None, None)
  File "/home/future/wwwroot/news/env/local/lib/python2.7/site-packages/sqlalchemy/engine/base.py", line 1116, in _handle_dbapi_exception
    exc_info
  File "/home/future/wwwroot/news/env/local/lib/python2.7/site-packages/sqlalchemy/util/compat.py", line 189, in raise_from_cause
    reraise(type(exception), exception, tb=exc_tb)
  File "/home/future/wwwroot/news/env/local/lib/python2.7/site-packages/sqlalchemy/engine/base.py", line 885, in _execute_context
    conn = self._revalidate_connection()
  File "/home/future/wwwroot/news/env/local/lib/python2.7/site-packages/sqlalchemy/engine/base.py", line 241, in _revalidate_connection
    "Can't reconnect until invalid "
StatementError: Can't reconnect until invalid transaction is rolled back (original cause: InvalidRequestError: Can't reconnect until invalid transaction is rolled back) u'SELECT news_article.id AS news_article_id, news_article.categoryid AS news_article_categoryid, news_article.title AS news_article_title, news_article.publisher AS news_article_publisher, news_article.author AS news_article_author, news_article.editor AS news_article_editor, news_article.`publishTime` AS `news_article_publishTime`, news_article.`updateTime` AS `news_article_updateTime`, news_article.content AS news_article_content, news_article.views AS news_article_views, news_article.state AS news_article_state, news_article.checker1 AS news_article_checker1, news_article.checker2 AS news_article_checker2 \nFROM news_article \nWHERE news_article.id = %s \n LIMIT %s' [immutabledict({})]
2014-10-15 13:00:36,916 ERROR: ERROR:500: IP:66.249.79.36 REQUEST URL:http://news.future.org.cn/article/22946 [in /home/future/wwwroot/news/news/controller/errorHandler.py:7]
2014-10-15 13:00:38,307 ERROR: Header:From: googlebot(at)googlebot.com
Content-Length: 
User-Agent: Mozilla/5.0 (compatible; Googlebot/2.1; +http://www.google.com/bot.html)
Connection: Keep-alive
Host: news.future.org.cn
Accept: */*
Content-Type: 
Accept-Encoding: gzip,deflate

 [in /home/future/wwwroot/news/news/controller/errorHandler.py:8]
2014-10-15 14:04:03,301 ERROR: Exception on /article/58246 [GET] [in /usr/lib/python2.7/dist-packages/flask/app.py:1423]
Traceback (most recent call last):
  File "/usr/lib/python2.7/dist-packages/flask/app.py", line 1817, in wsgi_app
    response = self.full_dispatch_request()
  File "/usr/lib/python2.7/dist-packages/flask/app.py", line 1477, in full_dispatch_request
    rv = self.handle_user_exception(e)
  File "/usr/lib/python2.7/dist-packages/flask/app.py", line 1381, in handle_user_exception
    reraise(exc_type, exc_value, tb)
  File "/usr/lib/python2.7/dist-packages/flask/app.py", line 1475, in full_dispatch_request
    rv = self.dispatch_request()
  File "/usr/lib/python2.7/dist-packages/flask/app.py", line 1461, in dispatch_request
    return self.view_functions[rule.endpoint](**req.view_args)
  File "/home/future/wwwroot/news/news/controller/article.py", line 88, in viewfrontArticle
    article=db_article.Article().getArticleByid(id)
  File "/home/future/wwwroot/news/news/model/article.py", line 96, in getArticleByid
    return session.query(Article).filter(Article.id == id).first()
  File "/home/future/wwwroot/news/env/local/lib/python2.7/site-packages/sqlalchemy/orm/query.py", line 2334, in first
    ret = list(self[0:1])
  File "/home/future/wwwroot/news/env/local/lib/python2.7/site-packages/sqlalchemy/orm/query.py", line 2201, in __getitem__
    return list(res)
  File "/home/future/wwwroot/news/env/local/lib/python2.7/site-packages/sqlalchemy/orm/query.py", line 2405, in __iter__
    return self._execute_and_instances(context)
  File "/home/future/wwwroot/news/env/local/lib/python2.7/site-packages/sqlalchemy/orm/query.py", line 2420, in _execute_and_instances
    result = conn.execute(querycontext.statement, self._params)
  File "/home/future/wwwroot/news/env/local/lib/python2.7/site-packages/sqlalchemy/engine/base.py", line 727, in execute
    return meth(self, multiparams, params)
  File "/home/future/wwwroot/news/env/local/lib/python2.7/site-packages/sqlalchemy/sql/elements.py", line 322, in _execute_on_connection
    return connection._execute_clauseelement(self, multiparams, params)
  File "/home/future/wwwroot/news/env/local/lib/python2.7/site-packages/sqlalchemy/engine/base.py", line 824, in _execute_clauseelement
    compiled_sql, distilled_params
  File "/home/future/wwwroot/news/env/local/lib/python2.7/site-packages/sqlalchemy/engine/base.py", line 891, in _execute_context
    None, None)
  File "/home/future/wwwroot/news/env/local/lib/python2.7/site-packages/sqlalchemy/engine/base.py", line 1116, in _handle_dbapi_exception
    exc_info
  File "/home/future/wwwroot/news/env/local/lib/python2.7/site-packages/sqlalchemy/util/compat.py", line 189, in raise_from_cause
    reraise(type(exception), exception, tb=exc_tb)
  File "/home/future/wwwroot/news/env/local/lib/python2.7/site-packages/sqlalchemy/engine/base.py", line 885, in _execute_context
    conn = self._revalidate_connection()
  File "/home/future/wwwroot/news/env/local/lib/python2.7/site-packages/sqlalchemy/engine/base.py", line 241, in _revalidate_connection
    "Can't reconnect until invalid "
StatementError: Can't reconnect until invalid transaction is rolled back (original cause: InvalidRequestError: Can't reconnect until invalid transaction is rolled back) u'SELECT news_article.id AS news_article_id, news_article.categoryid AS news_article_categoryid, news_article.title AS news_article_title, news_article.publisher AS news_article_publisher, news_article.author AS news_article_author, news_article.editor AS news_article_editor, news_article.`publishTime` AS `news_article_publishTime`, news_article.`updateTime` AS `news_article_updateTime`, news_article.content AS news_article_content, news_article.views AS news_article_views, news_article.state AS news_article_state, news_article.checker1 AS news_article_checker1, news_article.checker2 AS news_article_checker2 \nFROM news_article \nWHERE news_article.id = %s \n LIMIT %s' [immutabledict({})]
2014-10-15 14:04:04,949 ERROR: ERROR:500: IP:113.57.183.127 REQUEST URL:http://news.future.org.cn/article/58246 [in /home/future/wwwroot/news/news/controller/errorHandler.py:7]
2014-10-15 14:04:06,140 ERROR: Header:Cookie: CNZZDATA1000537224=750545220-1413193085-%7C1413193085
Content-Length: 
User-Agent: Mozilla/5.0 (iPhone; CPU iPhone OS 7_1_2 like Mac OS X) AppleWebKit/537.51.2 (KHTML, like Gecko) Mobile/11D257 QQ/5.1.1.97
Connection: keep-alive
Host: news.future.org.cn
Accept: text/html,application/xhtml+xml,application/xml;q=0.9,*/*;q=0.8
Accept-Language: zh-cn
Content-Type: 
Accept-Encoding: gzip, deflate

 [in /home/future/wwwroot/news/news/controller/errorHandler.py:8]
2014-10-15 15:23:18,911 ERROR: Exception on /article/58267 [GET] [in /usr/lib/python2.7/dist-packages/flask/app.py:1423]
Traceback (most recent call last):
  File "/usr/lib/python2.7/dist-packages/flask/app.py", line 1817, in wsgi_app
    response = self.full_dispatch_request()
  File "/usr/lib/python2.7/dist-packages/flask/app.py", line 1477, in full_dispatch_request
    rv = self.handle_user_exception(e)
  File "/usr/lib/python2.7/dist-packages/flask/app.py", line 1381, in handle_user_exception
    reraise(exc_type, exc_value, tb)
  File "/usr/lib/python2.7/dist-packages/flask/app.py", line 1475, in full_dispatch_request
    rv = self.dispatch_request()
  File "/usr/lib/python2.7/dist-packages/flask/app.py", line 1461, in dispatch_request
    return self.view_functions[rule.endpoint](**req.view_args)
  File "/home/future/wwwroot/news/news/controller/article.py", line 88, in viewfrontArticle
    article=db_article.Article().getArticleByid(id)
  File "/home/future/wwwroot/news/news/model/article.py", line 96, in getArticleByid
    return session.query(Article).filter(Article.id == id).first()
  File "/home/future/wwwroot/news/env/local/lib/python2.7/site-packages/sqlalchemy/orm/query.py", line 2334, in first
    ret = list(self[0:1])
  File "/home/future/wwwroot/news/env/local/lib/python2.7/site-packages/sqlalchemy/orm/query.py", line 2201, in __getitem__
    return list(res)
  File "/home/future/wwwroot/news/env/local/lib/python2.7/site-packages/sqlalchemy/orm/query.py", line 2405, in __iter__
    return self._execute_and_instances(context)
  File "/home/future/wwwroot/news/env/local/lib/python2.7/site-packages/sqlalchemy/orm/query.py", line 2420, in _execute_and_instances
    result = conn.execute(querycontext.statement, self._params)
  File "/home/future/wwwroot/news/env/local/lib/python2.7/site-packages/sqlalchemy/engine/base.py", line 727, in execute
    return meth(self, multiparams, params)
  File "/home/future/wwwroot/news/env/local/lib/python2.7/site-packages/sqlalchemy/sql/elements.py", line 322, in _execute_on_connection
    return connection._execute_clauseelement(self, multiparams, params)
  File "/home/future/wwwroot/news/env/local/lib/python2.7/site-packages/sqlalchemy/engine/base.py", line 824, in _execute_clauseelement
    compiled_sql, distilled_params
  File "/home/future/wwwroot/news/env/local/lib/python2.7/site-packages/sqlalchemy/engine/base.py", line 891, in _execute_context
    None, None)
  File "/home/future/wwwroot/news/env/local/lib/python2.7/site-packages/sqlalchemy/engine/base.py", line 1116, in _handle_dbapi_exception
    exc_info
  File "/home/future/wwwroot/news/env/local/lib/python2.7/site-packages/sqlalchemy/util/compat.py", line 189, in raise_from_cause
    reraise(type(exception), exception, tb=exc_tb)
  File "/home/future/wwwroot/news/env/local/lib/python2.7/site-packages/sqlalchemy/engine/base.py", line 885, in _execute_context
    conn = self._revalidate_connection()
  File "/home/future/wwwroot/news/env/local/lib/python2.7/site-packages/sqlalchemy/engine/base.py", line 241, in _revalidate_connection
    "Can't reconnect until invalid "
StatementError: Can't reconnect until invalid transaction is rolled back (original cause: InvalidRequestError: Can't reconnect until invalid transaction is rolled back) u'SELECT news_article.id AS news_article_id, news_article.categoryid AS news_article_categoryid, news_article.title AS news_article_title, news_article.publisher AS news_article_publisher, news_article.author AS news_article_author, news_article.editor AS news_article_editor, news_article.`publishTime` AS `news_article_publishTime`, news_article.`updateTime` AS `news_article_updateTime`, news_article.content AS news_article_content, news_article.views AS news_article_views, news_article.state AS news_article_state, news_article.checker1 AS news_article_checker1, news_article.checker2 AS news_article_checker2 \nFROM news_article \nWHERE news_article.id = %s \n LIMIT %s' [immutabledict({})]
2014-10-15 15:23:19,104 ERROR: ERROR:500: IP:101.226.61.142 REQUEST URL:http://news.future.org.cn/article/58267 [in /home/future/wwwroot/news/news/controller/errorHandler.py:7]
2014-10-15 15:23:19,326 ERROR: Header:Qpr-Loop: V1
Content-Length: 
Accept-Charset: utf-8, iso-8859-1, utf-16, *;q=0.7
User-Agent: Mozilla/5.0 (Linux; U; Android 4.2.2; zh-cn; H30-T00 Build/HuaweiH30-T00) AppleWebKit/533.1 (KHTML, like Gecko)Version/4.0 MQQBrowser/5.3 Mobile Safari/533.1 V1_AND_SQ_4.7.0_122_YYB_D QQ/4.7.0.2155
Connection: close
Q-Proxy-Wanip: 101.226.102.229
Q-Proxy-Type: 2433
Q-Guid: 1674616ff165f8aca3c2dcd8132488cb
Q-Auth: 8a5cfe8ddd7c34e473cebc55739b3025fad83ef98bfeed45
Host: news.future.org.cn
Accept: application/vnd.wap.xhtml+xml, text/vnd.wap.wml, application/xhtml+xml, text/html, image/png, image/jpeg, image/gif, */*;q=0.1
Q-Proxy-Param: PROTOCOL=0,QUALITY=2,APN=cmnet,Q-SID=1413357898,SupportedImage=63
Q-Ua: ADRQBX53_GA_SDK_com.tencent.mobileqq_122/530995&X5MTT_3/025306&ADR&458014& H30-T00 &0&9378&Android4.2.2 &V3
X-Forwarded-For: 117.136.23.79
Accept-Language: zh-CN
Content-Type: 
Accept-Encoding: gzip

 [in /home/future/wwwroot/news/news/controller/errorHandler.py:8]
2014-10-15 16:56:56,351 ERROR: Exception on /article/57003 [GET] [in /usr/lib/python2.7/dist-packages/flask/app.py:1423]
Traceback (most recent call last):
  File "/usr/lib/python2.7/dist-packages/flask/app.py", line 1817, in wsgi_app
    response = self.full_dispatch_request()
  File "/usr/lib/python2.7/dist-packages/flask/app.py", line 1477, in full_dispatch_request
    rv = self.handle_user_exception(e)
  File "/usr/lib/python2.7/dist-packages/flask/app.py", line 1381, in handle_user_exception
    reraise(exc_type, exc_value, tb)
  File "/usr/lib/python2.7/dist-packages/flask/app.py", line 1475, in full_dispatch_request
    rv = self.dispatch_request()
  File "/usr/lib/python2.7/dist-packages/flask/app.py", line 1461, in dispatch_request
    return self.view_functions[rule.endpoint](**req.view_args)
  File "/home/future/wwwroot/news/news/controller/article.py", line 88, in viewfrontArticle
    article=db_article.Article().getArticleByid(id)
  File "/home/future/wwwroot/news/news/model/article.py", line 96, in getArticleByid
    return session.query(Article).filter(Article.id == id).first()
  File "/home/future/wwwroot/news/env/local/lib/python2.7/site-packages/sqlalchemy/orm/query.py", line 2334, in first
    ret = list(self[0:1])
  File "/home/future/wwwroot/news/env/local/lib/python2.7/site-packages/sqlalchemy/orm/query.py", line 2201, in __getitem__
    return list(res)
  File "/home/future/wwwroot/news/env/local/lib/python2.7/site-packages/sqlalchemy/orm/query.py", line 2405, in __iter__
    return self._execute_and_instances(context)
  File "/home/future/wwwroot/news/env/local/lib/python2.7/site-packages/sqlalchemy/orm/query.py", line 2420, in _execute_and_instances
    result = conn.execute(querycontext.statement, self._params)
  File "/home/future/wwwroot/news/env/local/lib/python2.7/site-packages/sqlalchemy/engine/base.py", line 727, in execute
    return meth(self, multiparams, params)
  File "/home/future/wwwroot/news/env/local/lib/python2.7/site-packages/sqlalchemy/sql/elements.py", line 322, in _execute_on_connection
    return connection._execute_clauseelement(self, multiparams, params)
  File "/home/future/wwwroot/news/env/local/lib/python2.7/site-packages/sqlalchemy/engine/base.py", line 824, in _execute_clauseelement
    compiled_sql, distilled_params
  File "/home/future/wwwroot/news/env/local/lib/python2.7/site-packages/sqlalchemy/engine/base.py", line 891, in _execute_context
    None, None)
  File "/home/future/wwwroot/news/env/local/lib/python2.7/site-packages/sqlalchemy/engine/base.py", line 1116, in _handle_dbapi_exception
    exc_info
  File "/home/future/wwwroot/news/env/local/lib/python2.7/site-packages/sqlalchemy/util/compat.py", line 189, in raise_from_cause
    reraise(type(exception), exception, tb=exc_tb)
  File "/home/future/wwwroot/news/env/local/lib/python2.7/site-packages/sqlalchemy/engine/base.py", line 885, in _execute_context
    conn = self._revalidate_connection()
  File "/home/future/wwwroot/news/env/local/lib/python2.7/site-packages/sqlalchemy/engine/base.py", line 241, in _revalidate_connection
    "Can't reconnect until invalid "
StatementError: Can't reconnect until invalid transaction is rolled back (original cause: InvalidRequestError: Can't reconnect until invalid transaction is rolled back) u'SELECT news_article.id AS news_article_id, news_article.categoryid AS news_article_categoryid, news_article.title AS news_article_title, news_article.publisher AS news_article_publisher, news_article.author AS news_article_author, news_article.editor AS news_article_editor, news_article.`publishTime` AS `news_article_publishTime`, news_article.`updateTime` AS `news_article_updateTime`, news_article.content AS news_article_content, news_article.views AS news_article_views, news_article.state AS news_article_state, news_article.checker1 AS news_article_checker1, news_article.checker2 AS news_article_checker2 \nFROM news_article \nWHERE news_article.id = %s \n LIMIT %s' [immutabledict({})]
2014-10-15 16:56:56,563 ERROR: ERROR:500: IP:220.181.108.94 REQUEST URL:http://news.future.org.cn/article/57003 [in /home/future/wwwroot/news/news/controller/errorHandler.py:7]
2014-10-15 16:56:56,751 ERROR: Header:Content-Length: 
User-Agent: Mozilla/5.0 (compatible; Baiduspider/2.0; +http://www.baidu.com/search/spider.html)
Connection: close
Host: news.future.org.cn
Accept: */*
Accept-Language: zh-cn,zh-tw
Content-Type: 
Accept-Encoding: gzip

 [in /home/future/wwwroot/news/news/controller/errorHandler.py:8]
2014-10-15 20:47:41,239 INFO: ERROR:404: IP:115.156.106.213 REQUEST URL:http://news.future.org.cn/favicon.ico [in /home/future/wwwroot/news/news/controller/errorHandler.py:19]
2014-10-15 20:47:41,241 INFO: Header:Content-Length: 
User-Agent: Mozilla/5.0 (Windows NT 6.1) AppleWebKit/537.36 (KHTML, like Gecko) Chrome/37.0.2062.120 Safari/537.36 OPR/24.0.1558.61
Connection: keep-alive
Host: news.future.org.cn
Accept-Language: zh-CN,zh;q=0.8
Content-Type: 
Accept-Encoding: gzip,deflate,lzma,sdch

 [in /home/future/wwwroot/news/news/controller/errorHandler.py:20]
2014-10-15 22:26:22,153 INFO: ERROR:404: IP:220.181.125.129 REQUEST URL:http://news.future.org.cn/articles/39409.html [in /home/future/wwwroot/news/news/controller/errorHandler.py:19]
2014-10-15 22:26:22,155 INFO: Header:If-Modified-Since: Sat, 23 Aug 2014 02:58:08 GMT
Content-Length: 
User-Agent: Sogou web spider/4.0(+http://www.sogou.com/docs/help/webmasters.htm#07)
Connection: close
Host: news.future.org.cn
Accept: */*
Accept-Language: zh-cn
Content-Type: 
Accept-Encoding: gzip,deflate

 [in /home/future/wwwroot/news/news/controller/errorHandler.py:20]
2014-10-16 10:31:43,306 ERROR: Exception on /article/56411 [GET] [in /usr/lib/python2.7/dist-packages/flask/app.py:1423]
Traceback (most recent call last):
  File "/usr/lib/python2.7/dist-packages/flask/app.py", line 1817, in wsgi_app
    response = self.full_dispatch_request()
  File "/usr/lib/python2.7/dist-packages/flask/app.py", line 1477, in full_dispatch_request
    rv = self.handle_user_exception(e)
  File "/usr/lib/python2.7/dist-packages/flask/app.py", line 1381, in handle_user_exception
    reraise(exc_type, exc_value, tb)
  File "/usr/lib/python2.7/dist-packages/flask/app.py", line 1475, in full_dispatch_request
    rv = self.dispatch_request()
  File "/usr/lib/python2.7/dist-packages/flask/app.py", line 1461, in dispatch_request
    return self.view_functions[rule.endpoint](**req.view_args)
  File "/home/future/wwwroot/news/news/controller/article.py", line 88, in viewfrontArticle
    article=db_article.Article().getArticleByid(id)
  File "/home/future/wwwroot/news/news/model/article.py", line 96, in getArticleByid
    return session.query(Article).filter(Article.id == id).first()
  File "/home/future/wwwroot/news/env/local/lib/python2.7/site-packages/sqlalchemy/orm/query.py", line 2334, in first
    ret = list(self[0:1])
  File "/home/future/wwwroot/news/env/local/lib/python2.7/site-packages/sqlalchemy/orm/query.py", line 2201, in __getitem__
    return list(res)
  File "/home/future/wwwroot/news/env/local/lib/python2.7/site-packages/sqlalchemy/orm/query.py", line 2405, in __iter__
    return self._execute_and_instances(context)
  File "/home/future/wwwroot/news/env/local/lib/python2.7/site-packages/sqlalchemy/orm/query.py", line 2420, in _execute_and_instances
    result = conn.execute(querycontext.statement, self._params)
  File "/home/future/wwwroot/news/env/local/lib/python2.7/site-packages/sqlalchemy/engine/base.py", line 727, in execute
    return meth(self, multiparams, params)
  File "/home/future/wwwroot/news/env/local/lib/python2.7/site-packages/sqlalchemy/sql/elements.py", line 322, in _execute_on_connection
    return connection._execute_clauseelement(self, multiparams, params)
  File "/home/future/wwwroot/news/env/local/lib/python2.7/site-packages/sqlalchemy/engine/base.py", line 824, in _execute_clauseelement
    compiled_sql, distilled_params
  File "/home/future/wwwroot/news/env/local/lib/python2.7/site-packages/sqlalchemy/engine/base.py", line 891, in _execute_context
    None, None)
  File "/home/future/wwwroot/news/env/local/lib/python2.7/site-packages/sqlalchemy/engine/base.py", line 1116, in _handle_dbapi_exception
    exc_info
  File "/home/future/wwwroot/news/env/local/lib/python2.7/site-packages/sqlalchemy/util/compat.py", line 189, in raise_from_cause
    reraise(type(exception), exception, tb=exc_tb)
  File "/home/future/wwwroot/news/env/local/lib/python2.7/site-packages/sqlalchemy/engine/base.py", line 885, in _execute_context
    conn = self._revalidate_connection()
  File "/home/future/wwwroot/news/env/local/lib/python2.7/site-packages/sqlalchemy/engine/base.py", line 241, in _revalidate_connection
    "Can't reconnect until invalid "
StatementError: Can't reconnect until invalid transaction is rolled back (original cause: InvalidRequestError: Can't reconnect until invalid transaction is rolled back) u'SELECT news_article.id AS news_article_id, news_article.categoryid AS news_article_categoryid, news_article.title AS news_article_title, news_article.publisher AS news_article_publisher, news_article.author AS news_article_author, news_article.editor AS news_article_editor, news_article.`publishTime` AS `news_article_publishTime`, news_article.`updateTime` AS `news_article_updateTime`, news_article.content AS news_article_content, news_article.views AS news_article_views, news_article.state AS news_article_state, news_article.checker1 AS news_article_checker1, news_article.checker2 AS news_article_checker2 \nFROM news_article \nWHERE news_article.id = %s \n LIMIT %s' [immutabledict({})]
2014-10-16 10:31:43,499 ERROR: ERROR:500: IP:101.226.167.196 REQUEST URL:http://news.future.org.cn/article/56411 [in /home/future/wwwroot/news/news/controller/errorHandler.py:7]
2014-10-16 10:31:43,693 ERROR: Header:Referer: http://news.future.org.cn/article/56411
Content-Length: 
User-Agent: Mozilla/5.0 (Windows NT 6.1) AppleWebKit/537.1 (KHTML, like Gecko) Chrome/21.0.1180.89 Safari/537.1; 360Spider
Connection: Keep-Alive
Host: news.future.org.cn
Accept: */*
Accept-Language: zh-CN
Content-Type: 
Accept-Encoding: deflate, gzip

 [in /home/future/wwwroot/news/news/controller/errorHandler.py:8]
2014-10-16 11:51:19,056 ERROR: Exception on /article/58257 [GET] [in /usr/lib/python2.7/dist-packages/flask/app.py:1423]
Traceback (most recent call last):
  File "/usr/lib/python2.7/dist-packages/flask/app.py", line 1817, in wsgi_app
    response = self.full_dispatch_request()
  File "/usr/lib/python2.7/dist-packages/flask/app.py", line 1477, in full_dispatch_request
    rv = self.handle_user_exception(e)
  File "/usr/lib/python2.7/dist-packages/flask/app.py", line 1381, in handle_user_exception
    reraise(exc_type, exc_value, tb)
  File "/usr/lib/python2.7/dist-packages/flask/app.py", line 1475, in full_dispatch_request
    rv = self.dispatch_request()
  File "/usr/lib/python2.7/dist-packages/flask/app.py", line 1461, in dispatch_request
    return self.view_functions[rule.endpoint](**req.view_args)
  File "/home/future/wwwroot/news/news/controller/article.py", line 88, in viewfrontArticle
    article=db_article.Article().getArticleByid(id)
  File "/home/future/wwwroot/news/news/model/article.py", line 96, in getArticleByid
    return session.query(Article).filter(Article.id == id).first()
  File "/home/future/wwwroot/news/env/local/lib/python2.7/site-packages/sqlalchemy/orm/query.py", line 2334, in first
    ret = list(self[0:1])
  File "/home/future/wwwroot/news/env/local/lib/python2.7/site-packages/sqlalchemy/orm/query.py", line 2201, in __getitem__
    return list(res)
  File "/home/future/wwwroot/news/env/local/lib/python2.7/site-packages/sqlalchemy/orm/query.py", line 2405, in __iter__
    return self._execute_and_instances(context)
  File "/home/future/wwwroot/news/env/local/lib/python2.7/site-packages/sqlalchemy/orm/query.py", line 2420, in _execute_and_instances
    result = conn.execute(querycontext.statement, self._params)
  File "/home/future/wwwroot/news/env/local/lib/python2.7/site-packages/sqlalchemy/engine/base.py", line 727, in execute
    return meth(self, multiparams, params)
  File "/home/future/wwwroot/news/env/local/lib/python2.7/site-packages/sqlalchemy/sql/elements.py", line 322, in _execute_on_connection
    return connection._execute_clauseelement(self, multiparams, params)
  File "/home/future/wwwroot/news/env/local/lib/python2.7/site-packages/sqlalchemy/engine/base.py", line 824, in _execute_clauseelement
    compiled_sql, distilled_params
  File "/home/future/wwwroot/news/env/local/lib/python2.7/site-packages/sqlalchemy/engine/base.py", line 891, in _execute_context
    None, None)
  File "/home/future/wwwroot/news/env/local/lib/python2.7/site-packages/sqlalchemy/engine/base.py", line 1116, in _handle_dbapi_exception
    exc_info
  File "/home/future/wwwroot/news/env/local/lib/python2.7/site-packages/sqlalchemy/util/compat.py", line 189, in raise_from_cause
    reraise(type(exception), exception, tb=exc_tb)
  File "/home/future/wwwroot/news/env/local/lib/python2.7/site-packages/sqlalchemy/engine/base.py", line 885, in _execute_context
    conn = self._revalidate_connection()
  File "/home/future/wwwroot/news/env/local/lib/python2.7/site-packages/sqlalchemy/engine/base.py", line 241, in _revalidate_connection
    "Can't reconnect until invalid "
StatementError: Can't reconnect until invalid transaction is rolled back (original cause: InvalidRequestError: Can't reconnect until invalid transaction is rolled back) u'SELECT news_article.id AS news_article_id, news_article.categoryid AS news_article_categoryid, news_article.title AS news_article_title, news_article.publisher AS news_article_publisher, news_article.author AS news_article_author, news_article.editor AS news_article_editor, news_article.`publishTime` AS `news_article_publishTime`, news_article.`updateTime` AS `news_article_updateTime`, news_article.content AS news_article_content, news_article.views AS news_article_views, news_article.state AS news_article_state, news_article.checker1 AS news_article_checker1, news_article.checker2 AS news_article_checker2 \nFROM news_article \nWHERE news_article.id = %s \n LIMIT %s' [immutabledict({})]
2014-10-16 11:51:19,269 ERROR: ERROR:500: IP:10.128.82.242 REQUEST URL:http://news.future.org.cn/article/58257 [in /home/future/wwwroot/news/news/controller/errorHandler.py:7]
2014-10-16 11:51:19,468 ERROR: Header:Content-Length: 
User-Agent: Mozilla/5.0 (Linux; U; Android 4.4.2; zh-cn; MI 3W Build/KVT49L) AppleWebKit/537.36 (KHTML, like Gecko) Version/4.0 Mobile Safari/537.36 XiaoMi/MiuiBrowser/2.0.1
Connection: keep-alive
X-Requested-With: com.android.browser
Host: news.future.org.cn
Accept: text/html,application/xhtml+xml,application/xml;q=0.9,image/webp,*/*;q=0.8
Accept-Language: zh-CN,en-US;q=0.8
Content-Type: 
Accept-Encoding: gzip,deflate

 [in /home/future/wwwroot/news/news/controller/errorHandler.py:8]
2014-10-16 14:27:44,973 ERROR: Exception on /article/58257 [GET] [in /usr/lib/python2.7/dist-packages/flask/app.py:1423]
Traceback (most recent call last):
  File "/usr/lib/python2.7/dist-packages/flask/app.py", line 1817, in wsgi_app
    response = self.full_dispatch_request()
  File "/usr/lib/python2.7/dist-packages/flask/app.py", line 1477, in full_dispatch_request
    rv = self.handle_user_exception(e)
  File "/usr/lib/python2.7/dist-packages/flask/app.py", line 1381, in handle_user_exception
    reraise(exc_type, exc_value, tb)
  File "/usr/lib/python2.7/dist-packages/flask/app.py", line 1475, in full_dispatch_request
    rv = self.dispatch_request()
  File "/usr/lib/python2.7/dist-packages/flask/app.py", line 1461, in dispatch_request
    return self.view_functions[rule.endpoint](**req.view_args)
  File "/home/future/wwwroot/news/news/controller/article.py", line 88, in viewfrontArticle
    article=db_article.Article().getArticleByid(id)
  File "/home/future/wwwroot/news/news/model/article.py", line 96, in getArticleByid
    return session.query(Article).filter(Article.id == id).first()
  File "/home/future/wwwroot/news/env/local/lib/python2.7/site-packages/sqlalchemy/orm/query.py", line 2334, in first
    ret = list(self[0:1])
  File "/home/future/wwwroot/news/env/local/lib/python2.7/site-packages/sqlalchemy/orm/query.py", line 2201, in __getitem__
    return list(res)
  File "/home/future/wwwroot/news/env/local/lib/python2.7/site-packages/sqlalchemy/orm/query.py", line 2405, in __iter__
    return self._execute_and_instances(context)
  File "/home/future/wwwroot/news/env/local/lib/python2.7/site-packages/sqlalchemy/orm/query.py", line 2420, in _execute_and_instances
    result = conn.execute(querycontext.statement, self._params)
  File "/home/future/wwwroot/news/env/local/lib/python2.7/site-packages/sqlalchemy/engine/base.py", line 727, in execute
    return meth(self, multiparams, params)
  File "/home/future/wwwroot/news/env/local/lib/python2.7/site-packages/sqlalchemy/sql/elements.py", line 322, in _execute_on_connection
    return connection._execute_clauseelement(self, multiparams, params)
  File "/home/future/wwwroot/news/env/local/lib/python2.7/site-packages/sqlalchemy/engine/base.py", line 824, in _execute_clauseelement
    compiled_sql, distilled_params
  File "/home/future/wwwroot/news/env/local/lib/python2.7/site-packages/sqlalchemy/engine/base.py", line 891, in _execute_context
    None, None)
  File "/home/future/wwwroot/news/env/local/lib/python2.7/site-packages/sqlalchemy/engine/base.py", line 1116, in _handle_dbapi_exception
    exc_info
  File "/home/future/wwwroot/news/env/local/lib/python2.7/site-packages/sqlalchemy/util/compat.py", line 189, in raise_from_cause
    reraise(type(exception), exception, tb=exc_tb)
  File "/home/future/wwwroot/news/env/local/lib/python2.7/site-packages/sqlalchemy/engine/base.py", line 885, in _execute_context
    conn = self._revalidate_connection()
  File "/home/future/wwwroot/news/env/local/lib/python2.7/site-packages/sqlalchemy/engine/base.py", line 241, in _revalidate_connection
    "Can't reconnect until invalid "
StatementError: Can't reconnect until invalid transaction is rolled back (original cause: InvalidRequestError: Can't reconnect until invalid transaction is rolled back) u'SELECT news_article.id AS news_article_id, news_article.categoryid AS news_article_categoryid, news_article.title AS news_article_title, news_article.publisher AS news_article_publisher, news_article.author AS news_article_author, news_article.editor AS news_article_editor, news_article.`publishTime` AS `news_article_publishTime`, news_article.`updateTime` AS `news_article_updateTime`, news_article.content AS news_article_content, news_article.views AS news_article_views, news_article.state AS news_article_state, news_article.checker1 AS news_article_checker1, news_article.checker2 AS news_article_checker2 \nFROM news_article \nWHERE news_article.id = %s \n LIMIT %s' [immutabledict({})]
2014-10-16 14:27:45,199 ERROR: ERROR:500: IP:123.151.42.48 REQUEST URL:http://news.future.org.cn/article/58257 [in /home/future/wwwroot/news/news/controller/errorHandler.py:7]
2014-10-16 14:27:45,396 ERROR: Header:Cookie: CNZZDATA1000537224=1344502976-1413201910-%7C1413201910
Qpr-Loop: V1
Content-Length: 
Accept-Charset: utf-8, iso-8859-1, utf-16, *;q=0.7
User-Agent: Mozilla/5.0 (Linux; U; Android 4.2.2; zh-cn; TCL Y910 Build/JDQ39) AppleWebKit/533.1 (KHTML, like Gecko)Version/4.0 MQQBrowser/5.4 Mobile Safari/533.1 V1_AND_SQ_5.1.1_158_YYB_D QQ/5.1.1.2245
Connection: close
Q-Proxy-Wanip: 0.0.0.0
Q-Proxy-Type: 2433
Q-Guid: b4c541af5483b59204f7207a13cc88cb
Q-Auth: 8586524e322c50474d7984ad80345fdeb29a04f1e3bff449
Host: news.future.org.cn
Accept: application/vnd.wap.xhtml+xml, text/vnd.wap.wml, application/xhtml+xml, text/html, image/png, image/jpeg, image/gif, */*;q=0.1
Q-Proxy-Param: PROTOCOL=0,QUALITY=2,APN=3gnet,Q-SID=1413440968,SupportedImage=63,yyb=1
Q-Ua: ADRQBX54_GA_SDK_com.tencent.mobileqq_158/541100&X5MTT_3/025405&ADR&6812014& TCLY910 &50079&9397&Android4.2.2 &V3
X-Forwarded-For: 113.57.246.239
Accept-Language: zh-CN
Content-Type: 
Accept-Encoding: gzip

 [in /home/future/wwwroot/news/news/controller/errorHandler.py:8]
2014-10-16 14:36:50,471 ERROR: Exception on /category/1 [GET] [in /usr/lib/python2.7/dist-packages/flask/app.py:1423]
Traceback (most recent call last):
  File "/usr/lib/python2.7/dist-packages/flask/app.py", line 1817, in wsgi_app
    response = self.full_dispatch_request()
  File "/usr/lib/python2.7/dist-packages/flask/app.py", line 1477, in full_dispatch_request
    rv = self.handle_user_exception(e)
  File "/usr/lib/python2.7/dist-packages/flask/app.py", line 1381, in handle_user_exception
    reraise(exc_type, exc_value, tb)
  File "/usr/lib/python2.7/dist-packages/flask/app.py", line 1475, in full_dispatch_request
    rv = self.dispatch_request()
  File "/usr/lib/python2.7/dist-packages/flask/app.py", line 1461, in dispatch_request
    return self.view_functions[rule.endpoint](**req.view_args)
  File "/home/future/wwwroot/news/news/controller/category.py", line 15, in viewCategory
    category=db_category.Category().getCategortByid(id)
  File "/home/future/wwwroot/news/news/model/category.py", line 61, in getCategortByid
    return session.query(Category).filter(Category.id == id).first()
  File "/home/future/wwwroot/news/env/local/lib/python2.7/site-packages/sqlalchemy/orm/query.py", line 2334, in first
    ret = list(self[0:1])
  File "/home/future/wwwroot/news/env/local/lib/python2.7/site-packages/sqlalchemy/orm/query.py", line 2201, in __getitem__
    return list(res)
  File "/home/future/wwwroot/news/env/local/lib/python2.7/site-packages/sqlalchemy/orm/query.py", line 2405, in __iter__
    return self._execute_and_instances(context)
  File "/home/future/wwwroot/news/env/local/lib/python2.7/site-packages/sqlalchemy/orm/query.py", line 2420, in _execute_and_instances
    result = conn.execute(querycontext.statement, self._params)
  File "/home/future/wwwroot/news/env/local/lib/python2.7/site-packages/sqlalchemy/engine/base.py", line 727, in execute
    return meth(self, multiparams, params)
  File "/home/future/wwwroot/news/env/local/lib/python2.7/site-packages/sqlalchemy/sql/elements.py", line 322, in _execute_on_connection
    return connection._execute_clauseelement(self, multiparams, params)
  File "/home/future/wwwroot/news/env/local/lib/python2.7/site-packages/sqlalchemy/engine/base.py", line 824, in _execute_clauseelement
    compiled_sql, distilled_params
  File "/home/future/wwwroot/news/env/local/lib/python2.7/site-packages/sqlalchemy/engine/base.py", line 891, in _execute_context
    None, None)
  File "/home/future/wwwroot/news/env/local/lib/python2.7/site-packages/sqlalchemy/engine/base.py", line 1116, in _handle_dbapi_exception
    exc_info
  File "/home/future/wwwroot/news/env/local/lib/python2.7/site-packages/sqlalchemy/util/compat.py", line 189, in raise_from_cause
    reraise(type(exception), exception, tb=exc_tb)
  File "/home/future/wwwroot/news/env/local/lib/python2.7/site-packages/sqlalchemy/engine/base.py", line 885, in _execute_context
    conn = self._revalidate_connection()
  File "/home/future/wwwroot/news/env/local/lib/python2.7/site-packages/sqlalchemy/engine/base.py", line 241, in _revalidate_connection
    "Can't reconnect until invalid "
StatementError: Can't reconnect until invalid transaction is rolled back (original cause: InvalidRequestError: Can't reconnect until invalid transaction is rolled back) u'SELECT news_category.id AS news_category_id, news_category.parentid AS news_category_parentid, news_category.categoryname AS news_category_categoryname \nFROM news_category \nWHERE news_category.id = %s \n LIMIT %s' [immutabledict({})]
2014-10-16 14:36:52,086 ERROR: ERROR:500: IP:123.66.130.54 REQUEST URL:http://news.future.org.cn/category/1 [in /home/future/wwwroot/news/news/controller/errorHandler.py:7]
2014-10-16 14:36:53,654 ERROR: Header:Referer: http://www.future.org.cn/
Content-Length: 
User-Agent: Mozilla/4.0 (compatible; MSIE 8.0; Windows NT 5.1; Trident/4.0; QQDownload 735)
Connection: Keep-Alive
Cookie: CNZZDATA1000537224=736551240-1413441509-http%253A%252F%252Fwww.future.org.cn%252F%7C1413441509
Host: news.future.org.cn
Accept: image/gif, image/jpeg, image/pjpeg, image/pjpeg, application/x-shockwave-flash, */*
Accept-Language: zh-cn
Content-Type: 
Accept-Encoding: gzip, deflate

 [in /home/future/wwwroot/news/news/controller/errorHandler.py:8]
2014-10-16 15:04:59,507 ERROR: Exception on /article/58267 [GET] [in /usr/lib/python2.7/dist-packages/flask/app.py:1423]
Traceback (most recent call last):
  File "/usr/lib/python2.7/dist-packages/flask/app.py", line 1817, in wsgi_app
    response = self.full_dispatch_request()
  File "/usr/lib/python2.7/dist-packages/flask/app.py", line 1477, in full_dispatch_request
    rv = self.handle_user_exception(e)
  File "/usr/lib/python2.7/dist-packages/flask/app.py", line 1381, in handle_user_exception
    reraise(exc_type, exc_value, tb)
  File "/usr/lib/python2.7/dist-packages/flask/app.py", line 1475, in full_dispatch_request
    rv = self.dispatch_request()
  File "/usr/lib/python2.7/dist-packages/flask/app.py", line 1461, in dispatch_request
    return self.view_functions[rule.endpoint](**req.view_args)
  File "/home/future/wwwroot/news/news/controller/article.py", line 88, in viewfrontArticle
    article=db_article.Article().getArticleByid(id)
  File "/home/future/wwwroot/news/news/model/article.py", line 96, in getArticleByid
    return session.query(Article).filter(Article.id == id).first()
  File "/home/future/wwwroot/news/env/local/lib/python2.7/site-packages/sqlalchemy/orm/query.py", line 2334, in first
    ret = list(self[0:1])
  File "/home/future/wwwroot/news/env/local/lib/python2.7/site-packages/sqlalchemy/orm/query.py", line 2201, in __getitem__
    return list(res)
  File "/home/future/wwwroot/news/env/local/lib/python2.7/site-packages/sqlalchemy/orm/query.py", line 2405, in __iter__
    return self._execute_and_instances(context)
  File "/home/future/wwwroot/news/env/local/lib/python2.7/site-packages/sqlalchemy/orm/query.py", line 2420, in _execute_and_instances
    result = conn.execute(querycontext.statement, self._params)
  File "/home/future/wwwroot/news/env/local/lib/python2.7/site-packages/sqlalchemy/engine/base.py", line 727, in execute
    return meth(self, multiparams, params)
  File "/home/future/wwwroot/news/env/local/lib/python2.7/site-packages/sqlalchemy/sql/elements.py", line 322, in _execute_on_connection
    return connection._execute_clauseelement(self, multiparams, params)
  File "/home/future/wwwroot/news/env/local/lib/python2.7/site-packages/sqlalchemy/engine/base.py", line 824, in _execute_clauseelement
    compiled_sql, distilled_params
  File "/home/future/wwwroot/news/env/local/lib/python2.7/site-packages/sqlalchemy/engine/base.py", line 891, in _execute_context
    None, None)
  File "/home/future/wwwroot/news/env/local/lib/python2.7/site-packages/sqlalchemy/engine/base.py", line 1116, in _handle_dbapi_exception
    exc_info
  File "/home/future/wwwroot/news/env/local/lib/python2.7/site-packages/sqlalchemy/util/compat.py", line 189, in raise_from_cause
    reraise(type(exception), exception, tb=exc_tb)
  File "/home/future/wwwroot/news/env/local/lib/python2.7/site-packages/sqlalchemy/engine/base.py", line 885, in _execute_context
    conn = self._revalidate_connection()
  File "/home/future/wwwroot/news/env/local/lib/python2.7/site-packages/sqlalchemy/engine/base.py", line 241, in _revalidate_connection
    "Can't reconnect until invalid "
StatementError: Can't reconnect until invalid transaction is rolled back (original cause: InvalidRequestError: Can't reconnect until invalid transaction is rolled back) u'SELECT news_article.id AS news_article_id, news_article.categoryid AS news_article_categoryid, news_article.title AS news_article_title, news_article.publisher AS news_article_publisher, news_article.author AS news_article_author, news_article.editor AS news_article_editor, news_article.`publishTime` AS `news_article_publishTime`, news_article.`updateTime` AS `news_article_updateTime`, news_article.content AS news_article_content, news_article.views AS news_article_views, news_article.state AS news_article_state, news_article.checker1 AS news_article_checker1, news_article.checker2 AS news_article_checker2 \nFROM news_article \nWHERE news_article.id = %s \n LIMIT %s' [immutabledict({})]
2014-10-16 15:04:59,737 ERROR: ERROR:500: IP:113.57.182.219 REQUEST URL:http://news.future.org.cn/article/58267 [in /home/future/wwwroot/news/news/controller/errorHandler.py:7]
2014-10-16 15:04:59,944 ERROR: Header:Content-Length: 
User-Agent: Mozilla/5.0 (iPhone; CPU iPhone OS 8_0 like Mac OS X) AppleWebKit/600.1.4 (KHTML, like Gecko) Mobile/12A365 QQ/5.1.1.97
Connection: keep-alive
Host: news.future.org.cn
Accept: text/html,application/xhtml+xml,application/xml;q=0.9,*/*;q=0.8
Accept-Language: zh-cn
Content-Type: 
Accept-Encoding: gzip, deflate

 [in /home/future/wwwroot/news/news/controller/errorHandler.py:8]
