2014-10-14 16:49:19,226 INFO: ERROR:404: IP:117.136.23.59 REQUEST URL:http://news.future.org.cn/favicon.ico [in /home/future/wwwroot/news/news/controller/errorHandler.py:19]
2014-10-14 16:49:19,227 INFO: Header:Referer: http://news.future.org.cn/article/58267
Content-Length: 
Accept-Charset: utf-8, iso-8859-1, utf-16, *;q=0.7
User-Agent: Mozilla/5.0 (Linux; U; Android 4.1.2; zh-cn; HUAWEI G525-U00 Build/HuaweiG525-U00) AppleWebKit/537.36 (KHTML, like Gecko)Version/4.0 MQQBrowser/5.4 Mobile Safari/537.36
Connection: keep-alive
Cookie: CNZZDATA1000537224=1718567281-1413276643-http%253A%252F%252Fwww.future.org.cn%252F%7C1413276643
Host: news.future.org.cn
Accept: text/xml, text/html, application/xhtml+xml, image/png, text/plain, */*;q=0.8
Accept-Language: zh-CN
Content-Type: 
Accept-Encoding: gzip

 [in /home/future/wwwroot/news/news/controller/errorHandler.py:20]
2014-10-14 20:29:27,915 INFO: ERROR:404: IP:113.57.255.1 REQUEST URL:http://news.future.org.cn:80/static/upload/ueditor/file/20141009/1412846534623648.docx&range=0 [in /home/future/wwwroot/news/news/controller/errorHandler.py:19]
2014-10-14 20:29:27,916 INFO: Header:Content-Length: 
User-Agent: Dalvik/1.6.0 (Linux; U; Android 4.1.1; MI 2SC MIUI/JLB39.0)
Connection: Keep-Alive
X-Online-Host: news.future.org.cn:80
Range: bytes=0-
Host: news.future.org.cn:80
Accept: */*
Net-Type: gprs
X-Up-Bear-Type: WCDMA
Content-Type: 
Accept-Encoding: identity

 [in /home/future/wwwroot/news/news/controller/errorHandler.py:20]
2014-10-14 20:29:38,615 INFO: ERROR:404: IP:113.57.255.1 REQUEST URL:http://news.future.org.cn:80/static/upload/ueditor/file/20141009/1412846534139339.doc&range=0 [in /home/future/wwwroot/news/news/controller/errorHandler.py:19]
2014-10-14 20:29:38,616 INFO: Header:Content-Length: 
User-Agent: Dalvik/1.6.0 (Linux; U; Android 4.1.1; MI 2SC MIUI/JLB39.0)
Connection: Keep-Alive
X-Online-Host: news.future.org.cn:80
Range: bytes=0-
Host: news.future.org.cn:80
Accept: */*
Net-Type: gprs
X-Up-Bear-Type: WCDMA
Content-Type: 
Accept-Encoding: identity

 [in /home/future/wwwroot/news/news/controller/errorHandler.py:20]
2014-10-14 20:29:39,947 INFO: ERROR:404: IP:113.57.255.1 REQUEST URL:http://news.future.org.cn:80/static/upload/ueditor/file/20141009/1412846534623648.docx&range=95 [in /home/future/wwwroot/news/news/controller/errorHandler.py:19]
2014-10-14 20:29:39,948 INFO: Header:Content-Length: 
User-Agent: Dalvik/1.6.0 (Linux; U; Android 4.1.1; MI 2SC MIUI/JLB39.0)
Connection: Keep-Alive
X-Online-Host: news.future.org.cn:80
Range: bytes=95-
Host: news.future.org.cn:80
Accept: */*
Net-Type: gprs
X-Up-Bear-Type: WCDMA
Content-Type: 
Accept-Encoding: identity

 [in /home/future/wwwroot/news/news/controller/errorHandler.py:20]
2014-10-15 08:55:57,013 ERROR: Exception on /article/58246 [GET] [in /usr/lib/python2.7/dist-packages/flask/app.py:1423]
Traceback (most recent call last):
  File "/usr/lib/python2.7/dist-packages/flask/app.py", line 1817, in wsgi_app
    response = self.full_dispatch_request()
  File "/usr/lib/python2.7/dist-packages/flask/app.py", line 1477, in full_dispatch_request
    rv = self.handle_user_exception(e)
  File "/usr/lib/python2.7/dist-packages/flask/app.py", line 1381, in handle_user_exception
    reraise(exc_type, exc_value, tb)
  File "/usr/lib/python2.7/dist-packages/flask/app.py", line 1475, in full_dispatch_request
    rv = self.dispatch_request()
  File "/usr/lib/python2.7/dist-packages/flask/app.py", line 1461, in dispatch_request
    return self.view_functions[rule.endpoint](**req.view_args)
  File "/home/future/wwwroot/news/news/controller/article.py", line 88, in viewfrontArticle
    article=db_article.Article().getArticleByid(id)
  File "/home/future/wwwroot/news/news/model/article.py", line 96, in getArticleByid
    return session.query(Article).filter(Article.id == id).first()
  File "/home/future/wwwroot/news/env/local/lib/python2.7/site-packages/sqlalchemy/orm/query.py", line 2334, in first
    ret = list(self[0:1])
  File "/home/future/wwwroot/news/env/local/lib/python2.7/site-packages/sqlalchemy/orm/query.py", line 2201, in __getitem__
    return list(res)
  File "/home/future/wwwroot/news/env/local/lib/python2.7/site-packages/sqlalchemy/orm/query.py", line 2405, in __iter__
    return self._execute_and_instances(context)
  File "/home/future/wwwroot/news/env/local/lib/python2.7/site-packages/sqlalchemy/orm/query.py", line 2420, in _execute_and_instances
    result = conn.execute(querycontext.statement, self._params)
  File "/home/future/wwwroot/news/env/local/lib/python2.7/site-packages/sqlalchemy/engine/base.py", line 727, in execute
    return meth(self, multiparams, params)
  File "/home/future/wwwroot/news/env/local/lib/python2.7/site-packages/sqlalchemy/sql/elements.py", line 322, in _execute_on_connection
    return connection._execute_clauseelement(self, multiparams, params)
  File "/home/future/wwwroot/news/env/local/lib/python2.7/site-packages/sqlalchemy/engine/base.py", line 824, in _execute_clauseelement
    compiled_sql, distilled_params
  File "/home/future/wwwroot/news/env/local/lib/python2.7/site-packages/sqlalchemy/engine/base.py", line 954, in _execute_context
    context)
  File "/home/future/wwwroot/news/env/local/lib/python2.7/site-packages/sqlalchemy/engine/base.py", line 1116, in _handle_dbapi_exception
    exc_info
  File "/home/future/wwwroot/news/env/local/lib/python2.7/site-packages/sqlalchemy/util/compat.py", line 189, in raise_from_cause
    reraise(type(exception), exception, tb=exc_tb)
  File "/home/future/wwwroot/news/env/local/lib/python2.7/site-packages/sqlalchemy/engine/base.py", line 947, in _execute_context
    context)
  File "/home/future/wwwroot/news/env/local/lib/python2.7/site-packages/sqlalchemy/engine/default.py", line 435, in do_execute
    cursor.execute(statement, parameters)
  File "/usr/local/lib/python2.7/dist-packages/MySQLdb/cursors.py", line 205, in execute
    self.errorhandler(self, exc, value)
  File "/usr/local/lib/python2.7/dist-packages/MySQLdb/connections.py", line 36, in defaulterrorhandler
    raise errorclass, errorvalue
OperationalError: (OperationalError) (2006, 'MySQL server has gone away') 'SELECT news_article.id AS news_article_id, news_article.categoryid AS news_article_categoryid, news_article.title AS news_article_title, news_article.publisher AS news_article_publisher, news_article.author AS news_article_author, news_article.editor AS news_article_editor, news_article.`publishTime` AS `news_article_publishTime`, news_article.`updateTime` AS `news_article_updateTime`, news_article.content AS news_article_content, news_article.views AS news_article_views, news_article.state AS news_article_state, news_article.checker1 AS news_article_checker1, news_article.checker2 AS news_article_checker2 \nFROM news_article \nWHERE news_article.id = %s \n LIMIT %s' (58246, 1)
2014-10-15 08:55:58,201 ERROR: ERROR:500: IP:117.136.23.16 REQUEST URL:http://news.future.org.cn/article/58246 [in /home/future/wwwroot/news/news/controller/errorHandler.py:7]
2014-10-15 08:55:59,534 ERROR: Header:X-Wap-Profile: http://wap1.huawei.com/uaprof/HUAWEI_H30-T00_UAProfile.xml
Referer: http://120.196.211.226/cgi-bin/httpconn?htcmd=0x6ff0080&u=http%3A%2F%2Fnews.future.org.cn%2Farticle%2F58246%3FmType%3DGroup%26from%3Dandroidqq&wap=3&qq-pf-to=mqq.c2c&uin=1034466182&originuin=82465213
Content-Length: 
Accept-Charset: utf-8, utf-16, *;q=0.7
User-Agent: Mozilla/5.0 (Linux; U; Android 4.2.2; zh-cn; H30-T00 Build/HuaweiH30-T00) AppleWebKit/534.30 (KHTML, like Gecko) Version/4.0 Mobile Safari/534.30 V1_AND_SQ_5.1.1_158_YYB_D QQ/5.1.1.2245
Connection: keep-alive
X-Requested-With: com.tencent.mobileqq
Host: news.future.org.cn
Accept: text/html,application/xhtml+xml,application/xml;q=0.9,*/*;q=0.8
Accept-Language: zh-CN, en-US
Content-Type: 
Accept-Encoding: gzip,deflate

 [in /home/future/wwwroot/news/news/controller/errorHandler.py:8]
2014-10-15 09:27:02,263 ERROR: Exception on /article/58257 [GET] [in /usr/lib/python2.7/dist-packages/flask/app.py:1423]
Traceback (most recent call last):
  File "/usr/lib/python2.7/dist-packages/flask/app.py", line 1817, in wsgi_app
    response = self.full_dispatch_request()
  File "/usr/lib/python2.7/dist-packages/flask/app.py", line 1477, in full_dispatch_request
    rv = self.handle_user_exception(e)
  File "/usr/lib/python2.7/dist-packages/flask/app.py", line 1381, in handle_user_exception
    reraise(exc_type, exc_value, tb)
  File "/usr/lib/python2.7/dist-packages/flask/app.py", line 1475, in full_dispatch_request
    rv = self.dispatch_request()
  File "/usr/lib/python2.7/dist-packages/flask/app.py", line 1461, in dispatch_request
    return self.view_functions[rule.endpoint](**req.view_args)
  File "/home/future/wwwroot/news/news/controller/article.py", line 88, in viewfrontArticle
    article=db_article.Article().getArticleByid(id)
  File "/home/future/wwwroot/news/news/model/article.py", line 96, in getArticleByid
    return session.query(Article).filter(Article.id == id).first()
  File "/home/future/wwwroot/news/env/local/lib/python2.7/site-packages/sqlalchemy/orm/query.py", line 2334, in first
    ret = list(self[0:1])
  File "/home/future/wwwroot/news/env/local/lib/python2.7/site-packages/sqlalchemy/orm/query.py", line 2201, in __getitem__
    return list(res)
  File "/home/future/wwwroot/news/env/local/lib/python2.7/site-packages/sqlalchemy/orm/query.py", line 2405, in __iter__
    return self._execute_and_instances(context)
  File "/home/future/wwwroot/news/env/local/lib/python2.7/site-packages/sqlalchemy/orm/query.py", line 2420, in _execute_and_instances
    result = conn.execute(querycontext.statement, self._params)
  File "/home/future/wwwroot/news/env/local/lib/python2.7/site-packages/sqlalchemy/engine/base.py", line 727, in execute
    return meth(self, multiparams, params)
  File "/home/future/wwwroot/news/env/local/lib/python2.7/site-packages/sqlalchemy/sql/elements.py", line 322, in _execute_on_connection
    return connection._execute_clauseelement(self, multiparams, params)
  File "/home/future/wwwroot/news/env/local/lib/python2.7/site-packages/sqlalchemy/engine/base.py", line 824, in _execute_clauseelement
    compiled_sql, distilled_params
  File "/home/future/wwwroot/news/env/local/lib/python2.7/site-packages/sqlalchemy/engine/base.py", line 891, in _execute_context
    None, None)
  File "/home/future/wwwroot/news/env/local/lib/python2.7/site-packages/sqlalchemy/engine/base.py", line 1116, in _handle_dbapi_exception
    exc_info
  File "/home/future/wwwroot/news/env/local/lib/python2.7/site-packages/sqlalchemy/util/compat.py", line 189, in raise_from_cause
    reraise(type(exception), exception, tb=exc_tb)
  File "/home/future/wwwroot/news/env/local/lib/python2.7/site-packages/sqlalchemy/engine/base.py", line 885, in _execute_context
    conn = self._revalidate_connection()
  File "/home/future/wwwroot/news/env/local/lib/python2.7/site-packages/sqlalchemy/engine/base.py", line 241, in _revalidate_connection
    "Can't reconnect until invalid "
StatementError: Can't reconnect until invalid transaction is rolled back (original cause: InvalidRequestError: Can't reconnect until invalid transaction is rolled back) u'SELECT news_article.id AS news_article_id, news_article.categoryid AS news_article_categoryid, news_article.title AS news_article_title, news_article.publisher AS news_article_publisher, news_article.author AS news_article_author, news_article.editor AS news_article_editor, news_article.`publishTime` AS `news_article_publishTime`, news_article.`updateTime` AS `news_article_updateTime`, news_article.content AS news_article_content, news_article.views AS news_article_views, news_article.state AS news_article_state, news_article.checker1 AS news_article_checker1, news_article.checker2 AS news_article_checker2 \nFROM news_article \nWHERE news_article.id = %s \n LIMIT %s' [immutabledict({})]
2014-10-15 09:27:02,457 ERROR: ERROR:500: IP:123.151.42.47 REQUEST URL:http://news.future.org.cn/article/58257 [in /home/future/wwwroot/news/news/controller/errorHandler.py:7]
2014-10-15 09:27:02,659 ERROR: Header:Qpr-Loop: V1
Content-Length: 
Accept-Charset: utf-8, iso-8859-1, utf-16, *;q=0.7
User-Agent: Mozilla/5.0 (Linux; U; Android 4.1.1; zh-cn; MI 2A Build/JRO03L) AppleWebKit/533.1 (KHTML, like Gecko)Version/4.0 MQQBrowser/5.3 Mobile Safari/533.1 MicroMessenger/5.4.0.66_r807534.480 NetType/3gnet
Connection: close
Q-Proxy-Wanip: 0.0.0.0
Q-Proxy-Type: 2433
Q-Guid: ec8e9b950cedee465b85e62213db88cb
Q-Auth: 60391d61ab7d6b40a1e667ddfa1a8725472c6aa403647ab6
Host: news.future.org.cn
Accept: application/vnd.wap.xhtml+xml, text/vnd.wap.wml, application/xhtml+xml, text/html, image/png, image/jpeg, image/gif, */*;q=0.1
Q-Proxy-Param: PROTOCOL=0,QUALITY=2,APN=3gnet,Q-SID=1413336526,SupportedImage=63
Q-Ua: ADRQBX53_GA_SDK_com.tencent.mm_480/530995&X5MTT_3/025306&ADR&458014& MI2A &50079&9378&Android4.1.1 &V3
X-Forwarded-For: 113.57.182.123
Accept-Language: zh-CN
Content-Type: 
Accept-Encoding: gzip

 [in /home/future/wwwroot/news/news/controller/errorHandler.py:8]
2014-10-15 12:37:55,927 INFO: ERROR:404: IP:42.156.138.108 REQUEST URL:http://news.future.org.cn/articles/73797.html [in /home/future/wwwroot/news/news/controller/errorHandler.py:19]
2014-10-15 12:37:55,928 INFO: Header:Content-Length: 
User-Agent: YisouSpider
Connection: Keep-Alive
Host: news.future.org.cn
Accept: */*
Accept-Language: zh-cn,en-us,zh-tw,en-gb,en;
Content-Type: 
Accept-Encoding: gzip

 [in /home/future/wwwroot/news/news/controller/errorHandler.py:20]
2014-10-15 13:13:23,679 ERROR: Exception on /article/58246 [GET] [in /usr/lib/python2.7/dist-packages/flask/app.py:1423]
Traceback (most recent call last):
  File "/usr/lib/python2.7/dist-packages/flask/app.py", line 1817, in wsgi_app
    response = self.full_dispatch_request()
  File "/usr/lib/python2.7/dist-packages/flask/app.py", line 1477, in full_dispatch_request
    rv = self.handle_user_exception(e)
  File "/usr/lib/python2.7/dist-packages/flask/app.py", line 1381, in handle_user_exception
    reraise(exc_type, exc_value, tb)
  File "/usr/lib/python2.7/dist-packages/flask/app.py", line 1475, in full_dispatch_request
    rv = self.dispatch_request()
  File "/usr/lib/python2.7/dist-packages/flask/app.py", line 1461, in dispatch_request
    return self.view_functions[rule.endpoint](**req.view_args)
  File "/home/future/wwwroot/news/news/controller/article.py", line 88, in viewfrontArticle
    article=db_article.Article().getArticleByid(id)
  File "/home/future/wwwroot/news/news/model/article.py", line 96, in getArticleByid
    return session.query(Article).filter(Article.id == id).first()
  File "/home/future/wwwroot/news/env/local/lib/python2.7/site-packages/sqlalchemy/orm/query.py", line 2334, in first
    ret = list(self[0:1])
  File "/home/future/wwwroot/news/env/local/lib/python2.7/site-packages/sqlalchemy/orm/query.py", line 2201, in __getitem__
    return list(res)
  File "/home/future/wwwroot/news/env/local/lib/python2.7/site-packages/sqlalchemy/orm/query.py", line 2405, in __iter__
    return self._execute_and_instances(context)
  File "/home/future/wwwroot/news/env/local/lib/python2.7/site-packages/sqlalchemy/orm/query.py", line 2420, in _execute_and_instances
    result = conn.execute(querycontext.statement, self._params)
  File "/home/future/wwwroot/news/env/local/lib/python2.7/site-packages/sqlalchemy/engine/base.py", line 727, in execute
    return meth(self, multiparams, params)
  File "/home/future/wwwroot/news/env/local/lib/python2.7/site-packages/sqlalchemy/sql/elements.py", line 322, in _execute_on_connection
    return connection._execute_clauseelement(self, multiparams, params)
  File "/home/future/wwwroot/news/env/local/lib/python2.7/site-packages/sqlalchemy/engine/base.py", line 824, in _execute_clauseelement
    compiled_sql, distilled_params
  File "/home/future/wwwroot/news/env/local/lib/python2.7/site-packages/sqlalchemy/engine/base.py", line 891, in _execute_context
    None, None)
  File "/home/future/wwwroot/news/env/local/lib/python2.7/site-packages/sqlalchemy/engine/base.py", line 1116, in _handle_dbapi_exception
    exc_info
  File "/home/future/wwwroot/news/env/local/lib/python2.7/site-packages/sqlalchemy/util/compat.py", line 189, in raise_from_cause
    reraise(type(exception), exception, tb=exc_tb)
  File "/home/future/wwwroot/news/env/local/lib/python2.7/site-packages/sqlalchemy/engine/base.py", line 885, in _execute_context
    conn = self._revalidate_connection()
  File "/home/future/wwwroot/news/env/local/lib/python2.7/site-packages/sqlalchemy/engine/base.py", line 241, in _revalidate_connection
    "Can't reconnect until invalid "
StatementError: Can't reconnect until invalid transaction is rolled back (original cause: InvalidRequestError: Can't reconnect until invalid transaction is rolled back) u'SELECT news_article.id AS news_article_id, news_article.categoryid AS news_article_categoryid, news_article.title AS news_article_title, news_article.publisher AS news_article_publisher, news_article.author AS news_article_author, news_article.editor AS news_article_editor, news_article.`publishTime` AS `news_article_publishTime`, news_article.`updateTime` AS `news_article_updateTime`, news_article.content AS news_article_content, news_article.views AS news_article_views, news_article.state AS news_article_state, news_article.checker1 AS news_article_checker1, news_article.checker2 AS news_article_checker2 \nFROM news_article \nWHERE news_article.id = %s \n LIMIT %s' [immutabledict({})]
2014-10-15 13:13:23,925 ERROR: ERROR:500: IP:171.83.63.188 REQUEST URL:http://news.future.org.cn/article/58246 [in /home/future/wwwroot/news/news/controller/errorHandler.py:7]
2014-10-15 13:13:24,183 ERROR: Header:Content-Length: 
Accept-Charset: utf-8, iso-8859-1, utf-16, *;q=0.7
User-Agent: Mozilla/5.0 (Linux; U; Android 4.4.2; zh-cn; SM-G9008V Build/KOT49H) AppleWebKit/533.1 (KHTML, like Gecko)Version/4.0 MQQBrowser/5.2 Mobile Safari/533.1 V1_AND_SQ_5.1.0_156_YYB_D QQ/5.1.0.2240
Connection: keep-alive
Host: news.future.org.cn
Accept: application/vnd.wap.xhtml+xml, text/vnd.wap.wml, application/xhtml+xml, text/html, image/png, image/jpeg, image/gif, */*;q=0.1
Accept-Language: zh-CN
Content-Type: 
Accept-Encoding: gzip

 [in /home/future/wwwroot/news/news/controller/errorHandler.py:8]
2014-10-15 15:15:37,840 ERROR: Exception on /article/22936 [GET] [in /usr/lib/python2.7/dist-packages/flask/app.py:1423]
Traceback (most recent call last):
  File "/usr/lib/python2.7/dist-packages/flask/app.py", line 1817, in wsgi_app
    response = self.full_dispatch_request()
  File "/usr/lib/python2.7/dist-packages/flask/app.py", line 1477, in full_dispatch_request
    rv = self.handle_user_exception(e)
  File "/usr/lib/python2.7/dist-packages/flask/app.py", line 1381, in handle_user_exception
    reraise(exc_type, exc_value, tb)
  File "/usr/lib/python2.7/dist-packages/flask/app.py", line 1475, in full_dispatch_request
    rv = self.dispatch_request()
  File "/usr/lib/python2.7/dist-packages/flask/app.py", line 1461, in dispatch_request
    return self.view_functions[rule.endpoint](**req.view_args)
  File "/home/future/wwwroot/news/news/controller/article.py", line 88, in viewfrontArticle
    article=db_article.Article().getArticleByid(id)
  File "/home/future/wwwroot/news/news/model/article.py", line 96, in getArticleByid
    return session.query(Article).filter(Article.id == id).first()
  File "/home/future/wwwroot/news/env/local/lib/python2.7/site-packages/sqlalchemy/orm/query.py", line 2334, in first
    ret = list(self[0:1])
  File "/home/future/wwwroot/news/env/local/lib/python2.7/site-packages/sqlalchemy/orm/query.py", line 2201, in __getitem__
    return list(res)
  File "/home/future/wwwroot/news/env/local/lib/python2.7/site-packages/sqlalchemy/orm/query.py", line 2405, in __iter__
    return self._execute_and_instances(context)
  File "/home/future/wwwroot/news/env/local/lib/python2.7/site-packages/sqlalchemy/orm/query.py", line 2420, in _execute_and_instances
    result = conn.execute(querycontext.statement, self._params)
  File "/home/future/wwwroot/news/env/local/lib/python2.7/site-packages/sqlalchemy/engine/base.py", line 727, in execute
    return meth(self, multiparams, params)
  File "/home/future/wwwroot/news/env/local/lib/python2.7/site-packages/sqlalchemy/sql/elements.py", line 322, in _execute_on_connection
    return connection._execute_clauseelement(self, multiparams, params)
  File "/home/future/wwwroot/news/env/local/lib/python2.7/site-packages/sqlalchemy/engine/base.py", line 824, in _execute_clauseelement
    compiled_sql, distilled_params
  File "/home/future/wwwroot/news/env/local/lib/python2.7/site-packages/sqlalchemy/engine/base.py", line 891, in _execute_context
    None, None)
  File "/home/future/wwwroot/news/env/local/lib/python2.7/site-packages/sqlalchemy/engine/base.py", line 1116, in _handle_dbapi_exception
    exc_info
  File "/home/future/wwwroot/news/env/local/lib/python2.7/site-packages/sqlalchemy/util/compat.py", line 189, in raise_from_cause
    reraise(type(exception), exception, tb=exc_tb)
  File "/home/future/wwwroot/news/env/local/lib/python2.7/site-packages/sqlalchemy/engine/base.py", line 885, in _execute_context
    conn = self._revalidate_connection()
  File "/home/future/wwwroot/news/env/local/lib/python2.7/site-packages/sqlalchemy/engine/base.py", line 241, in _revalidate_connection
    "Can't reconnect until invalid "
StatementError: Can't reconnect until invalid transaction is rolled back (original cause: InvalidRequestError: Can't reconnect until invalid transaction is rolled back) u'SELECT news_article.id AS news_article_id, news_article.categoryid AS news_article_categoryid, news_article.title AS news_article_title, news_article.publisher AS news_article_publisher, news_article.author AS news_article_author, news_article.editor AS news_article_editor, news_article.`publishTime` AS `news_article_publishTime`, news_article.`updateTime` AS `news_article_updateTime`, news_article.content AS news_article_content, news_article.views AS news_article_views, news_article.state AS news_article_state, news_article.checker1 AS news_article_checker1, news_article.checker2 AS news_article_checker2 \nFROM news_article \nWHERE news_article.id = %s \n LIMIT %s' [immutabledict({})]
2014-10-15 15:15:39,146 ERROR: ERROR:500: IP:66.249.79.28 REQUEST URL:http://news.future.org.cn/article/22936 [in /home/future/wwwroot/news/news/controller/errorHandler.py:7]
2014-10-15 15:15:40,760 ERROR: Header:From: googlebot(at)googlebot.com
Content-Length: 
User-Agent: Mozilla/5.0 (compatible; Googlebot/2.1; +http://www.google.com/bot.html)
Connection: Keep-alive
Host: news.future.org.cn
Accept: */*
Content-Type: 
Accept-Encoding: gzip,deflate

 [in /home/future/wwwroot/news/news/controller/errorHandler.py:8]
2014-10-15 16:19:42,246 INFO: ERROR:404: IP:157.55.39.240 REQUEST URL:http://news.future.org.cn/articles/73523.html [in /home/future/wwwroot/news/news/controller/errorHandler.py:19]
2014-10-15 16:19:42,246 INFO: Header:From: bingbot(at)microsoft.com
Content-Length: 
User-Agent: Mozilla/5.0 (compatible; bingbot/2.0; +http://www.bing.com/bingbot.htm)
Connection: Keep-Alive
Pragma: no-cache
Host: news.future.org.cn
Cache-Control: no-cache
Accept: */*
Content-Type: 
Accept-Encoding: gzip, deflate

 [in /home/future/wwwroot/news/news/controller/errorHandler.py:20]
2014-10-15 20:08:08,257 ERROR: Exception on /article/58246 [GET] [in /usr/lib/python2.7/dist-packages/flask/app.py:1423]
Traceback (most recent call last):
  File "/usr/lib/python2.7/dist-packages/flask/app.py", line 1817, in wsgi_app
    response = self.full_dispatch_request()
  File "/usr/lib/python2.7/dist-packages/flask/app.py", line 1477, in full_dispatch_request
    rv = self.handle_user_exception(e)
  File "/usr/lib/python2.7/dist-packages/flask/app.py", line 1381, in handle_user_exception
    reraise(exc_type, exc_value, tb)
  File "/usr/lib/python2.7/dist-packages/flask/app.py", line 1475, in full_dispatch_request
    rv = self.dispatch_request()
  File "/usr/lib/python2.7/dist-packages/flask/app.py", line 1461, in dispatch_request
    return self.view_functions[rule.endpoint](**req.view_args)
  File "/home/future/wwwroot/news/news/controller/article.py", line 88, in viewfrontArticle
    article=db_article.Article().getArticleByid(id)
  File "/home/future/wwwroot/news/news/model/article.py", line 96, in getArticleByid
    return session.query(Article).filter(Article.id == id).first()
  File "/home/future/wwwroot/news/env/local/lib/python2.7/site-packages/sqlalchemy/orm/query.py", line 2334, in first
    ret = list(self[0:1])
  File "/home/future/wwwroot/news/env/local/lib/python2.7/site-packages/sqlalchemy/orm/query.py", line 2201, in __getitem__
    return list(res)
  File "/home/future/wwwroot/news/env/local/lib/python2.7/site-packages/sqlalchemy/orm/query.py", line 2405, in __iter__
    return self._execute_and_instances(context)
  File "/home/future/wwwroot/news/env/local/lib/python2.7/site-packages/sqlalchemy/orm/query.py", line 2420, in _execute_and_instances
    result = conn.execute(querycontext.statement, self._params)
  File "/home/future/wwwroot/news/env/local/lib/python2.7/site-packages/sqlalchemy/engine/base.py", line 727, in execute
    return meth(self, multiparams, params)
  File "/home/future/wwwroot/news/env/local/lib/python2.7/site-packages/sqlalchemy/sql/elements.py", line 322, in _execute_on_connection
    return connection._execute_clauseelement(self, multiparams, params)
  File "/home/future/wwwroot/news/env/local/lib/python2.7/site-packages/sqlalchemy/engine/base.py", line 824, in _execute_clauseelement
    compiled_sql, distilled_params
  File "/home/future/wwwroot/news/env/local/lib/python2.7/site-packages/sqlalchemy/engine/base.py", line 891, in _execute_context
    None, None)
  File "/home/future/wwwroot/news/env/local/lib/python2.7/site-packages/sqlalchemy/engine/base.py", line 1116, in _handle_dbapi_exception
    exc_info
  File "/home/future/wwwroot/news/env/local/lib/python2.7/site-packages/sqlalchemy/util/compat.py", line 189, in raise_from_cause
    reraise(type(exception), exception, tb=exc_tb)
  File "/home/future/wwwroot/news/env/local/lib/python2.7/site-packages/sqlalchemy/engine/base.py", line 885, in _execute_context
    conn = self._revalidate_connection()
  File "/home/future/wwwroot/news/env/local/lib/python2.7/site-packages/sqlalchemy/engine/base.py", line 241, in _revalidate_connection
    "Can't reconnect until invalid "
StatementError: Can't reconnect until invalid transaction is rolled back (original cause: InvalidRequestError: Can't reconnect until invalid transaction is rolled back) u'SELECT news_article.id AS news_article_id, news_article.categoryid AS news_article_categoryid, news_article.title AS news_article_title, news_article.publisher AS news_article_publisher, news_article.author AS news_article_author, news_article.editor AS news_article_editor, news_article.`publishTime` AS `news_article_publishTime`, news_article.`updateTime` AS `news_article_updateTime`, news_article.content AS news_article_content, news_article.views AS news_article_views, news_article.state AS news_article_state, news_article.checker1 AS news_article_checker1, news_article.checker2 AS news_article_checker2 \nFROM news_article \nWHERE news_article.id = %s \n LIMIT %s' [immutabledict({})]
2014-10-15 20:08:13,854 ERROR: ERROR:500: IP:171.83.53.126 REQUEST URL:http://news.future.org.cn/article/58246 [in /home/future/wwwroot/news/news/controller/errorHandler.py:7]
2014-10-15 20:08:14,480 ERROR: Header:Cookie: CNZZDATA1000537224=210715198-1413374258-%7C1413374258
Content-Length: 
Accept-Charset: utf-8, iso-8859-1, utf-16, *;q=0.7
User-Agent: Mozilla/5.0 (Linux; U; Android 4.3; zh-cn; HM 1SW Build/JLS36C) AppleWebKit/533.1 (KHTML, like Gecko)Version/4.0 MQQBrowser/5.4 Mobile Safari/533.1 V1_AND_SQ_5.1.1_158_YYB_D QQ/5.1.1.2245
Connection: keep-alive
Host: news.future.org.cn
Accept: application/vnd.wap.xhtml+xml, text/vnd.wap.wml, application/xhtml+xml, text/html, image/png, image/jpeg, image/gif, */*;q=0.1
Accept-Language: zh-CN
Content-Type: 
Accept-Encoding: gzip

 [in /home/future/wwwroot/news/news/controller/errorHandler.py:8]
2014-10-15 21:08:27,789 INFO: ERROR:404: IP:220.181.125.129 REQUEST URL:http://news.future.org.cn/articles/28990.html [in /home/future/wwwroot/news/news/controller/errorHandler.py:19]
2014-10-15 21:08:27,790 INFO: Header:If-Modified-Since: Sat, 30 Aug 2014 05:01:28 GMT
Content-Length: 
User-Agent: Sogou web spider/4.0(+http://www.sogou.com/docs/help/webmasters.htm#07)
Connection: close
Host: news.future.org.cn
Accept: */*
Accept-Language: zh-cn
Content-Type: 
Accept-Encoding: gzip,deflate

 [in /home/future/wwwroot/news/news/controller/errorHandler.py:20]
2014-10-15 22:23:12,878 INFO: ERROR:404: IP:62.210.74.118 REQUEST URL:http://news.future.org.cn/articles/39468.html [in /home/future/wwwroot/news/news/controller/errorHandler.py:19]
2014-10-15 22:23:12,878 INFO: Header:Content-Length: 
User-Agent: Mozilla/5.0 (compatible; MJ12bot/v1.4.5; http://www.majestic12.co.uk/bot.php?+)
Connection: close
Host: news.future.org.cn
Accept: text/html,text/plain,text/xml,text/*,application/xml,application/xhtml+xml,application/rss+xml,application/atom+xml,application/rdf+xml
Accept-Language: zh
Content-Type: 
Accept-Encoding: gzip

 [in /home/future/wwwroot/news/news/controller/errorHandler.py:20]
2014-10-15 23:05:28,146 INFO: ERROR:404: IP:27.17.131.72 REQUEST URL:http://news.future.org.cn/favicon.ico [in /home/future/wwwroot/news/news/controller/errorHandler.py:19]
2014-10-15 23:05:28,147 INFO: Header:Cookie: CNZZDATA1000537224=1343832226-1413295550-%7C1413384031
Content-Length: 
User-Agent: Mozilla/5.0 (Windows NT 6.1; WOW64) AppleWebKit/537.36 (KHTML, like Gecko) Chrome/35.0.1916.153 UBrowser/3.0.1644.0 Safari/537.36
Connection: keep-alive
Host: news.future.org.cn
Accept: */*
Accept-Language: zh-CN,zh;q=0.8
Content-Type: 
Accept-Encoding: gzip,deflate,sdch

 [in /home/future/wwwroot/news/news/controller/errorHandler.py:20]
2014-10-16 11:06:32,569 ERROR: Exception on /article/58270 [GET] [in /usr/lib/python2.7/dist-packages/flask/app.py:1423]
Traceback (most recent call last):
  File "/usr/lib/python2.7/dist-packages/flask/app.py", line 1817, in wsgi_app
    response = self.full_dispatch_request()
  File "/usr/lib/python2.7/dist-packages/flask/app.py", line 1477, in full_dispatch_request
    rv = self.handle_user_exception(e)
  File "/usr/lib/python2.7/dist-packages/flask/app.py", line 1381, in handle_user_exception
    reraise(exc_type, exc_value, tb)
  File "/usr/lib/python2.7/dist-packages/flask/app.py", line 1475, in full_dispatch_request
    rv = self.dispatch_request()
  File "/usr/lib/python2.7/dist-packages/flask/app.py", line 1461, in dispatch_request
    return self.view_functions[rule.endpoint](**req.view_args)
  File "/home/future/wwwroot/news/news/controller/article.py", line 88, in viewfrontArticle
    article=db_article.Article().getArticleByid(id)
  File "/home/future/wwwroot/news/news/model/article.py", line 96, in getArticleByid
    return session.query(Article).filter(Article.id == id).first()
  File "/home/future/wwwroot/news/env/local/lib/python2.7/site-packages/sqlalchemy/orm/query.py", line 2334, in first
    ret = list(self[0:1])
  File "/home/future/wwwroot/news/env/local/lib/python2.7/site-packages/sqlalchemy/orm/query.py", line 2201, in __getitem__
    return list(res)
  File "/home/future/wwwroot/news/env/local/lib/python2.7/site-packages/sqlalchemy/orm/query.py", line 2405, in __iter__
    return self._execute_and_instances(context)
  File "/home/future/wwwroot/news/env/local/lib/python2.7/site-packages/sqlalchemy/orm/query.py", line 2420, in _execute_and_instances
    result = conn.execute(querycontext.statement, self._params)
  File "/home/future/wwwroot/news/env/local/lib/python2.7/site-packages/sqlalchemy/engine/base.py", line 727, in execute
    return meth(self, multiparams, params)
  File "/home/future/wwwroot/news/env/local/lib/python2.7/site-packages/sqlalchemy/sql/elements.py", line 322, in _execute_on_connection
    return connection._execute_clauseelement(self, multiparams, params)
  File "/home/future/wwwroot/news/env/local/lib/python2.7/site-packages/sqlalchemy/engine/base.py", line 824, in _execute_clauseelement
    compiled_sql, distilled_params
  File "/home/future/wwwroot/news/env/local/lib/python2.7/site-packages/sqlalchemy/engine/base.py", line 891, in _execute_context
    None, None)
  File "/home/future/wwwroot/news/env/local/lib/python2.7/site-packages/sqlalchemy/engine/base.py", line 1116, in _handle_dbapi_exception
    exc_info
  File "/home/future/wwwroot/news/env/local/lib/python2.7/site-packages/sqlalchemy/util/compat.py", line 189, in raise_from_cause
    reraise(type(exception), exception, tb=exc_tb)
  File "/home/future/wwwroot/news/env/local/lib/python2.7/site-packages/sqlalchemy/engine/base.py", line 885, in _execute_context
    conn = self._revalidate_connection()
  File "/home/future/wwwroot/news/env/local/lib/python2.7/site-packages/sqlalchemy/engine/base.py", line 241, in _revalidate_connection
    "Can't reconnect until invalid "
StatementError: Can't reconnect until invalid transaction is rolled back (original cause: InvalidRequestError: Can't reconnect until invalid transaction is rolled back) u'SELECT news_article.id AS news_article_id, news_article.categoryid AS news_article_categoryid, news_article.title AS news_article_title, news_article.publisher AS news_article_publisher, news_article.author AS news_article_author, news_article.editor AS news_article_editor, news_article.`publishTime` AS `news_article_publishTime`, news_article.`updateTime` AS `news_article_updateTime`, news_article.content AS news_article_content, news_article.views AS news_article_views, news_article.state AS news_article_state, news_article.checker1 AS news_article_checker1, news_article.checker2 AS news_article_checker2 \nFROM news_article \nWHERE news_article.id = %s \n LIMIT %s' [immutabledict({})]
2014-10-16 11:06:34,154 ERROR: ERROR:500: IP:157.55.39.110 REQUEST URL:http://news.future.org.cn/article/58270 [in /home/future/wwwroot/news/news/controller/errorHandler.py:7]
2014-10-16 11:06:35,620 ERROR: Header:From: bingbot(at)microsoft.com
Content-Length: 
User-Agent: Mozilla/5.0 (compatible; bingbot/2.0; +http://www.bing.com/bingbot.htm)
Connection: Keep-Alive
Pragma: no-cache
Host: news.future.org.cn
Cache-Control: no-cache
Accept: */*
Content-Type: 
Accept-Encoding: gzip, deflate

 [in /home/future/wwwroot/news/news/controller/errorHandler.py:8]
2014-10-16 13:39:19,003 ERROR: Exception on /article/58272 [GET] [in /usr/lib/python2.7/dist-packages/flask/app.py:1423]
Traceback (most recent call last):
  File "/usr/lib/python2.7/dist-packages/flask/app.py", line 1817, in wsgi_app
    response = self.full_dispatch_request()
  File "/usr/lib/python2.7/dist-packages/flask/app.py", line 1477, in full_dispatch_request
    rv = self.handle_user_exception(e)
  File "/usr/lib/python2.7/dist-packages/flask/app.py", line 1381, in handle_user_exception
    reraise(exc_type, exc_value, tb)
  File "/usr/lib/python2.7/dist-packages/flask/app.py", line 1475, in full_dispatch_request
    rv = self.dispatch_request()
  File "/usr/lib/python2.7/dist-packages/flask/app.py", line 1461, in dispatch_request
    return self.view_functions[rule.endpoint](**req.view_args)
  File "/home/future/wwwroot/news/news/controller/article.py", line 88, in viewfrontArticle
    article=db_article.Article().getArticleByid(id)
  File "/home/future/wwwroot/news/news/model/article.py", line 96, in getArticleByid
    return session.query(Article).filter(Article.id == id).first()
  File "/home/future/wwwroot/news/env/local/lib/python2.7/site-packages/sqlalchemy/orm/query.py", line 2334, in first
    ret = list(self[0:1])
  File "/home/future/wwwroot/news/env/local/lib/python2.7/site-packages/sqlalchemy/orm/query.py", line 2201, in __getitem__
    return list(res)
  File "/home/future/wwwroot/news/env/local/lib/python2.7/site-packages/sqlalchemy/orm/query.py", line 2405, in __iter__
    return self._execute_and_instances(context)
  File "/home/future/wwwroot/news/env/local/lib/python2.7/site-packages/sqlalchemy/orm/query.py", line 2420, in _execute_and_instances
    result = conn.execute(querycontext.statement, self._params)
  File "/home/future/wwwroot/news/env/local/lib/python2.7/site-packages/sqlalchemy/engine/base.py", line 727, in execute
    return meth(self, multiparams, params)
  File "/home/future/wwwroot/news/env/local/lib/python2.7/site-packages/sqlalchemy/sql/elements.py", line 322, in _execute_on_connection
    return connection._execute_clauseelement(self, multiparams, params)
  File "/home/future/wwwroot/news/env/local/lib/python2.7/site-packages/sqlalchemy/engine/base.py", line 824, in _execute_clauseelement
    compiled_sql, distilled_params
  File "/home/future/wwwroot/news/env/local/lib/python2.7/site-packages/sqlalchemy/engine/base.py", line 891, in _execute_context
    None, None)
  File "/home/future/wwwroot/news/env/local/lib/python2.7/site-packages/sqlalchemy/engine/base.py", line 1116, in _handle_dbapi_exception
    exc_info
  File "/home/future/wwwroot/news/env/local/lib/python2.7/site-packages/sqlalchemy/util/compat.py", line 189, in raise_from_cause
    reraise(type(exception), exception, tb=exc_tb)
  File "/home/future/wwwroot/news/env/local/lib/python2.7/site-packages/sqlalchemy/engine/base.py", line 885, in _execute_context
    conn = self._revalidate_connection()
  File "/home/future/wwwroot/news/env/local/lib/python2.7/site-packages/sqlalchemy/engine/base.py", line 241, in _revalidate_connection
    "Can't reconnect until invalid "
StatementError: Can't reconnect until invalid transaction is rolled back (original cause: InvalidRequestError: Can't reconnect until invalid transaction is rolled back) u'SELECT news_article.id AS news_article_id, news_article.categoryid AS news_article_categoryid, news_article.title AS news_article_title, news_article.publisher AS news_article_publisher, news_article.author AS news_article_author, news_article.editor AS news_article_editor, news_article.`publishTime` AS `news_article_publishTime`, news_article.`updateTime` AS `news_article_updateTime`, news_article.content AS news_article_content, news_article.views AS news_article_views, news_article.state AS news_article_state, news_article.checker1 AS news_article_checker1, news_article.checker2 AS news_article_checker2 \nFROM news_article \nWHERE news_article.id = %s \n LIMIT %s' [immutabledict({})]
2014-10-16 13:39:19,244 ERROR: ERROR:500: IP:27.17.131.149 REQUEST URL:http://news.future.org.cn/article/58272 [in /home/future/wwwroot/news/news/controller/errorHandler.py:7]
2014-10-16 13:39:19,465 ERROR: Header:Content-Length: 
User-Agent: Mozilla/5.0 (iPhone; CPU iPhone OS 8_0_2 like Mac OS X) AppleWebKit/600.1.4 (KHTML, like Gecko) Mobile/12A405 QQ/5.0.0.165
Connection: keep-alive
Host: news.future.org.cn
Accept: text/html,application/xhtml+xml,application/xml;q=0.9,*/*;q=0.8
Accept-Language: zh-cn
Content-Type: 
Accept-Encoding: gzip, deflate

 [in /home/future/wwwroot/news/news/controller/errorHandler.py:8]
2014-10-16 15:59:36,557 INFO: ERROR:404: IP:144.76.0.170 REQUEST URL:http://news.future.org.cn/articles/39072.html [in /home/future/wwwroot/news/news/controller/errorHandler.py:19]
2014-10-16 15:59:36,559 INFO: Header:Content-Length: 
User-Agent: Mozilla/5.0 (compatible; MJ12bot/v1.4.5; http://www.majestic12.co.uk/bot.php?+)
Connection: close
Host: news.future.org.cn
Accept: text/html,text/plain,text/xml,text/*,application/xml,application/xhtml+xml,application/rss+xml,application/atom+xml,application/rdf+xml
Accept-Language: zh
Content-Type: 
Accept-Encoding: gzip

 [in /home/future/wwwroot/news/news/controller/errorHandler.py:20]
